Workbook
Name COGS: LAMBDA((Snacks!$D$2 + Snacks!$K$2 - Snacks!$M$2) * Snacks!$E$2)

Sheet Transactions
B1: Anas | D1: Snacky
K2: Total income | L2: Revenue Income | M2: ads Income | N2: Total Spent | O2: Name
B3: =SUMIFS(C11:C501, B11:B501, "anas", D11:D501, "lyd", E11:E501, "money in") - SUMIFS(C11:C501, B11:B501, "anas", D11:D501, "lyd", E11:E501, "money out") -> -24360.5 | D3: =SUMIFS(C11:C566, B11:B566, "snacky", D11:D566, "lyd", E11:E566, "money in") - SUMIFS(C11:C566, B11:B566, "snacky", D11:D566, "lyd", E11:E566, "money out") -> 27469 | K3: =SUMIFS(C11:C501, B11:B501, "snacky", D11:D501, "lyd", E11:E501, "money in") -> 300808 | L3: =SUMIFS(C11:C501, B11:B501, "snacky", D11:D501, "lyd", E11:E501, "money in",F11:F501,"Revenue") -> 266258 | M3: =SUMIFS(C11:C501, B11:B501, "snacky", D11:D501, "lyd", E11:E501, "money in",F11:F501,"ads") -> 30000 | N3: =SUMIFS(C11:C501, B11:B501, "snacky", D11:D501, "lyd", E11:E501, "money out") -> 307626 | O3: Snacky
K4: =SUMIFS(C11:C501, B11:B501, "anas", D11:D501, "lyd", E11:E501, "money in") -> 11590 | N4: =SUMIFS(C11:C501, B11:B501, "anas", D11:D501, "lyd", E11:E501, "money out") -> 35950.5 | O4: Anas
B5: =SUMIFS(C11:C501, B11:B501, "anas", D11:D501, "$", E11:E501, "money in") - SUMIFS(C11:C501, B11:B501, "anas", D11:D501, "$", E11:E501, "money out") -> -418 | D5: =SUMIFS(C11:C501, B11:B501, "snacky", D11:D501, "$", E11:E501, "money in") - SUMIFS(C11:C501, B11:B501, "snakcy", D11:D501, "$", E11:E501, "money out") -> 0
B8: Transactions
K9: Average Monthly Net Revenue per Machine (including ad revenue)
A10: Date | B10: NameTransaction Amount | C10: Transaction | D10: Currency | E10: Money Flow | F10: Transaction Type | G10: Location | H10: Transaction Description
B11: Anas | C11: 1800 | D11: $ | E11: Money Out | H11: شراء اول مكينه | L11: =IFERROR(__xludf.DUMMYFUNCTION("VSTACK( {""Month"",""Total Revenue"",""HTMall"", ""HTLand"",""deplomacyMall"",""AlTahaddy"",""KhalijUniversity"",""AlmouasafatHospital"",""Istiklal"",""Ads (cash)"",""Total Rent"",""Net Revenue (excl Ads)""}, ARRAYFORMULA( LET( monthCol, TEX"&"T(DATEVALUE(A11:A666),""yyyy-mm""), amountCol, VALUE(SUBSTITUTE(C11:C666, "","","""")), placeCol, G11:G666, directionCol, E11:E666, typeCol, F11:F666, revOK, (directionCol=""Money In"")*(typeCol=""Revenue""), months, S"&"ORT(UNIQUE(FILTER(monthCol, revOK))), baseData, FILTER({monthCol, placeCol, amountCol}, revOK), HTMRev, IFERROR(VLOOKUP(months, QUERY(baseData, ""select Col1,sum(Col3) where Col2='HTMall' group by Col1"",0),2,false),0), "&" HTLRev, IFERROR(VLOOKUP(months, QUERY(baseData, ""select Col1,sum(Col3) where Col2='HTLand' group by Col1"",0),2,false),0), DPRev, IFERROR(VLOOKUP(months, QUERY(baseData, ""select Col1,sum(Col3) where Col2='deplomacyMall' group "&"by Col1"",0),2,false),0), ALTRev, IFERROR(VLOOKUP(months, QUERY(baseData, ""select Col1,sum(Col3) where Col2='AlTahaddy' group by Col1"",0),2,false),0), ALKRev, IFERROR(VLOOKUP(months, QU"&"ERY(baseData, ""select Col1,sum(Col3) where Col2='KhalijUniversity' group by Col1"",0),2,false),0), AHRev, IFERROR(VLOOKUP(months, QUERY(baseData, ""select Col1,sum(Col3) where Col2='AlmouasafatHospital' group by Col1"",0),2,false),0), "&" ISRev, IFERROR(VLOOKUP(months, QUERY(baseData, ""select Col1,sum(Col3) where Col2='Istiklal' group by Col1"",0),2,false),0), totalRev, HTMRev +HTLRev+ DPRev + ALTRev + ALKRev + AHRev +ISRev, adsBase, FILTER({monthCo"&"l, amountCol}, (directionCol=""Money In"")*(typeCol=""Ads"")), adsCash, IFERROR(VLOOKUP(months, QUERY(adsBase,""select Col1,sum(Col2) group by Col1"",0),2,false),0), rent, IF(HTMRev>0,1000,0)+IF(HTLRev>0,800,0)+IF(DPRev>0,500,0), netRev"&", totalRev - rent, HSTACK(months,totalRev,HTMRev,HTLRev,DPRev,ALTRev,ALKRev,AHRev,ISRev,adsCash,rent,netRev) ) ) ) "),"Month") -> Month | M11: =IFERROR(__xludf.DUMMYFUNCTION("""COMPUTED_VALUE"""),"Total Revenue") -> Total Revenue | N11: =IFERROR(__xludf.DUMMYFUNCTION("""COMPUTED_VALUE"""),"HTMall") -> HTMall | O11: =IFERROR(__xludf.DUMMYFUNCTION("""COMPUTED_VALUE"""),"HTLand") -> HTLand | P11: =IFERROR(__xludf.DUMMYFUNCTION("""COMPUTED_VALUE"""),"deplomacyMall") -> deplomacyMall | Q11: =IFERROR(__xludf.DUMMYFUNCTION("""COMPUTED_VALUE"""),"AlTahaddy") -> AlTahaddy | R11: =IFERROR(__xludf.DUMMYFUNCTION("""COMPUTED_VALUE"""),"KhalijUniversity") -> KhalijUniversity | S11: =IFERROR(__xludf.DUMMYFUNCTION("""COMPUTED_VALUE"""),"AlmouasafatHospital") -> AlmouasafatHospital | T11: =IFERROR(__xludf.DUMMYFUNCTION("""COMPUTED_VALUE"""),"Istiklal") -> Istiklal | U11: =IFERROR(__xludf.DUMMYFUNCTION("""COMPUTED_VALUE"""),"Ads (cash)") -> Ads (cash) | V11: =IFERROR(__xludf.DUMMYFUNCTION("""COMPUTED_VALUE"""),"Total Rent") -> Total Rent | W11: =IFERROR(__xludf.DUMMYFUNCTION("""COMPUTED_VALUE"""),"Net Revenue (excl Ads)") -> Net Revenue (excl Ads)
B12: Anas | C12: 363 | D12: $ | E12: Money Out | H12: سعر التوصيل من شاهين | L12: =IFERROR(__xludf.DUMMYFUNCTION("""COMPUTED_VALUE"""),"2024-08") -> 2024-08 | M12: =IFERROR(__xludf.DUMMYFUNCTION("""COMPUTED_VALUE"""),3283.0) -> 3283 | N12: =IFERROR(__xludf.DUMMYFUNCTION("""COMPUTED_VALUE"""),0.0) -> 0 | O12: =IFERROR(__xludf.DUMMYFUNCTION("""COMPUTED_VALUE"""),0.0) -> 0 | P12: =IFERROR(__xludf.DUMMYFUNCTION("""COMPUTED_VALUE"""),3283.0) -> 3283 | Q12: =IFERROR(__xludf.DUMMYFUNCTION("""COMPUTED_VALUE"""),0.0) -> 0 | R12: =IFERROR(__xludf.DUMMYFUNCTION("""COMPUTED_VALUE"""),0.0) -> 0 | S12: =IFERROR(__xludf.DUMMYFUNCTION("""COMPUTED_VALUE"""),0.0) -> 0 | T12: =IFERROR(__xludf.DUMMYFUNCTION("""COMPUTED_VALUE"""),0.0) -> 0 | U12: =IFERROR(__xludf.DUMMYFUNCTION("""COMPUTED_VALUE"""),2500.0) -> 2500 | V12: =IFERROR(__xludf.DUMMYFUNCTION("""COMPUTED_VALUE"""),500.0) -> 500 | W12: =IFERROR(__xludf.DUMMYFUNCTION("""COMPUTED_VALUE"""),2783.0) -> 2783
B13: Anas | C13: 10000 | D13: LYD | E13: Money Out | H13: توديع قيمه فالمصرف | L13: =IFERROR(__xludf.DUMMYFUNCTION("""COMPUTED_VALUE"""),"2024-09") -> 2024-09 | M13: =IFERROR(__xludf.DUMMYFUNCTION("""COMPUTED_VALUE"""),10159.0) -> 10159 | N13: =IFERROR(__xludf.DUMMYFUNCTION("""COMPUTED_VALUE"""),0.0) -> 0 | O13: =IFERROR(__xludf.DUMMYFUNCTION("""COMPUTED_VALUE"""),0.0) -> 0 | P13: =IFERROR(__xludf.DUMMYFUNCTION("""COMPUTED_VALUE"""),10159.0) -> 10159 | Q13: =IFERROR(__xludf.DUMMYFUNCTION("""COMPUTED_VALUE"""),0.0) -> 0 | R13: =IFERROR(__xludf.DUMMYFUNCTION("""COMPUTED_VALUE"""),0.0) -> 0 | S13: =IFERROR(__xludf.DUMMYFUNCTION("""COMPUTED_VALUE"""),0.0) -> 0 | T13: =IFERROR(__xludf.DUMMYFUNCTION("""COMPUTED_VALUE"""),0.0) -> 0 | U13: =IFERROR(__xludf.DUMMYFUNCTION("""COMPUTED_VALUE"""),0.0) -> 0 | V13: =IFERROR(__xludf.DUMMYFUNCTION("""COMPUTED_VALUE"""),500.0) -> 500 | W13: =IFERROR(__xludf.DUMMYFUNCTION("""COMPUTED_VALUE"""),9659.0) -> 9659
B14: Anas | C14: 1500 | D14: LYD | E14: Money Out | H14: فتح حساب في مصرف السراي | L14: =IFERROR(__xludf.DUMMYFUNCTION("""COMPUTED_VALUE"""),"2024-11") -> 2024-11 | M14: =IFERROR(__xludf.DUMMYFUNCTION("""COMPUTED_VALUE"""),836.0) -> 836 | N14: =IFERROR(__xludf.DUMMYFUNCTION("""COMPUTED_VALUE"""),0.0) -> 0 | O14: =IFERROR(__xludf.DUMMYFUNCTION("""COMPUTED_VALUE"""),0.0) -> 0 | P14: =IFERROR(__xludf.DUMMYFUNCTION("""COMPUTED_VALUE"""),836.0) -> 836 | Q14: =IFERROR(__xludf.DUMMYFUNCTION("""COMPUTED_VALUE"""),0.0) -> 0 | R14: =IFERROR(__xludf.DUMMYFUNCTION("""COMPUTED_VALUE"""),0.0) -> 0 | S14: =IFERROR(__xludf.DUMMYFUNCTION("""COMPUTED_VALUE"""),0.0) -> 0 | T14: =IFERROR(__xludf.DUMMYFUNCTION("""COMPUTED_VALUE"""),0.0) -> 0 | U14: =IFERROR(__xludf.DUMMYFUNCTION("""COMPUTED_VALUE"""),0.0) -> 0 | V14: =IFERROR(__xludf.DUMMYFUNCTION("""COMPUTED_VALUE"""),500.0) -> 500 | W14: =IFERROR(__xludf.DUMMYFUNCTION("""COMPUTED_VALUE"""),336.0) -> 336
B15: Anas | C15: 50 | D15: $ | E15: Money Out | H15: سعر تحويل من مصرف الى مصرف عند شراء الماكينه | L15: =IFERROR(__xludf.DUMMYFUNCTION("""COMPUTED_VALUE"""),"2024-12") -> 2024-12 | M15: =IFERROR(__xludf.DUMMYFUNCTION("""COMPUTED_VALUE"""),7553.0) -> 7553 | N15: =IFERROR(__xludf.DUMMYFUNCTION("""COMPUTED_VALUE"""),0.0) -> 0 | O15: =IFERROR(__xludf.DUMMYFUNCTION("""COMPUTED_VALUE"""),0.0) -> 0 | P15: =IFERROR(__xludf.DUMMYFUNCTION("""COMPUTED_VALUE"""),7553.0) -> 7553 | Q15: =IFERROR(__xludf.DUMMYFUNCTION("""COMPUTED_VALUE"""),0.0) -> 0 | R15: =IFERROR(__xludf.DUMMYFUNCTION("""COMPUTED_VALUE"""),0.0) -> 0 | S15: =IFERROR(__xludf.DUMMYFUNCTION("""COMPUTED_VALUE"""),0.0) -> 0 | T15: =IFERROR(__xludf.DUMMYFUNCTION("""COMPUTED_VALUE"""),0.0) -> 0 | U15: =IFERROR(__xludf.DUMMYFUNCTION("""COMPUTED_VALUE"""),2500.0) -> 2500 | V15: =IFERROR(__xludf.DUMMYFUNCTION("""COMPUTED_VALUE"""),500.0) -> 500 | W15: =IFERROR(__xludf.DUMMYFUNCTION("""COMPUTED_VALUE"""),7053.0) -> 7053
B16: Anas | C16: 750 | D16: LYD | E16: Money Out | F16: Product Restocking | H16: بضاعه | L16: =IFERROR(__xludf.DUMMYFUNCTION("""COMPUTED_VALUE"""),"2025-01") -> 2025-01 | M16: =IFERROR(__xludf.DUMMYFUNCTION("""COMPUTED_VALUE"""),8288.0) -> 8288 | N16: =IFERROR(__xludf.DUMMYFUNCTION("""COMPUTED_VALUE"""),0.0) -> 0 | O16: =IFERROR(__xludf.DUMMYFUNCTION("""COMPUTED_VALUE"""),0.0) -> 0 | P16: =IFERROR(__xludf.DUMMYFUNCTION("""COMPUTED_VALUE"""),8288.0) -> 8288 | Q16: =IFERROR(__xludf.DUMMYFUNCTION("""COMPUTED_VALUE"""),0.0) -> 0 | R16: =IFERROR(__xludf.DUMMYFUNCTION("""COMPUTED_VALUE"""),0.0) -> 0 | S16: =IFERROR(__xludf.DUMMYFUNCTION("""COMPUTED_VALUE"""),0.0) -> 0 | T16: =IFERROR(__xludf.DUMMYFUNCTION("""COMPUTED_VALUE"""),0.0) -> 0 | U16: =IFERROR(__xludf.DUMMYFUNCTION("""COMPUTED_VALUE"""),0.0) -> 0 | V16: =IFERROR(__xludf.DUMMYFUNCTION("""COMPUTED_VALUE"""),500.0) -> 500 | W16: =IFERROR(__xludf.DUMMYFUNCTION("""COMPUTED_VALUE"""),7788.0) -> 7788
B17: Anas | C17: 40 | D17: LYD | E17: Money Out | F17: Product Restocking | H17: بضاعه (مياه) | L17: =IFERROR(__xludf.DUMMYFUNCTION("""COMPUTED_VALUE"""),"2025-02") -> 2025-02 | M17: =IFERROR(__xludf.DUMMYFUNCTION("""COMPUTED_VALUE"""),7480.0) -> 7480 | N17: =IFERROR(__xludf.DUMMYFUNCTION("""COMPUTED_VALUE"""),0.0) -> 0 | O17: =IFERROR(__xludf.DUMMYFUNCTION("""COMPUTED_VALUE"""),0.0) -> 0 | P17: =IFERROR(__xludf.DUMMYFUNCTION("""COMPUTED_VALUE"""),7480.0) -> 7480 | Q17: =IFERROR(__xludf.DUMMYFUNCTION("""COMPUTED_VALUE"""),0.0) -> 0 | R17: =IFERROR(__xludf.DUMMYFUNCTION("""COMPUTED_VALUE"""),0.0) -> 0 | S17: =IFERROR(__xludf.DUMMYFUNCTION("""COMPUTED_VALUE"""),0.0) -> 0 | T17: =IFERROR(__xludf.DUMMYFUNCTION("""COMPUTED_VALUE"""),0.0) -> 0 | U17: =IFERROR(__xludf.DUMMYFUNCTION("""COMPUTED_VALUE"""),0.0) -> 0 | V17: =IFERROR(__xludf.DUMMYFUNCTION("""COMPUTED_VALUE"""),500.0) -> 500 | W17: =IFERROR(__xludf.DUMMYFUNCTION("""COMPUTED_VALUE"""),6980.0) -> 6980
B18: Anas | C18: 300 | D18: LYD | E18: Money Out | H18: توصيل الماكينه بالونش | L18: =IFERROR(__xludf.DUMMYFUNCTION("""COMPUTED_VALUE"""),"2025-03") -> 2025-03 | M18: =IFERROR(__xludf.DUMMYFUNCTION("""COMPUTED_VALUE"""),8925.0) -> 8925 | N18: =IFERROR(__xludf.DUMMYFUNCTION("""COMPUTED_VALUE"""),0.0) -> 0 | O18: =IFERROR(__xludf.DUMMYFUNCTION("""COMPUTED_VALUE"""),0.0) -> 0 | P18: =IFERROR(__xludf.DUMMYFUNCTION("""COMPUTED_VALUE"""),8925.0) -> 8925 | Q18: =IFERROR(__xludf.DUMMYFUNCTION("""COMPUTED_VALUE"""),0.0) -> 0 | R18: =IFERROR(__xludf.DUMMYFUNCTION("""COMPUTED_VALUE"""),0.0) -> 0 | S18: =IFERROR(__xludf.DUMMYFUNCTION("""COMPUTED_VALUE"""),0.0) -> 0 | T18: =IFERROR(__xludf.DUMMYFUNCTION("""COMPUTED_VALUE"""),0.0) -> 0 | U18: =IFERROR(__xludf.DUMMYFUNCTION("""COMPUTED_VALUE"""),1500.0) -> 1500 | V18: =IFERROR(__xludf.DUMMYFUNCTION("""COMPUTED_VALUE"""),500.0) -> 500 | W18: =IFERROR(__xludf.DUMMYFUNCTION("""COMPUTED_VALUE"""),8425.0) -> 8425
B19: Anas | C19: 70 | D19: LYD | E19: Money Out | H19: بضاعه (مياه) | L19: =IFERROR(__xludf.DUMMYFUNCTION("""COMPUTED_VALUE"""),"2025-04") -> 2025-04 | M19: =IFERROR(__xludf.DUMMYFUNCTION("""COMPUTED_VALUE"""),15847.0) -> 15847 | N19: =IFERROR(__xludf.DUMMYFUNCTION("""COMPUTED_VALUE"""),0.0) -> 0 | O19: =IFERROR(__xludf.DUMMYFUNCTION("""COMPUTED_VALUE"""),0.0) -> 0 | P19: =IFERROR(__xludf.DUMMYFUNCTION("""COMPUTED_VALUE"""),15847.0) -> 15847 | Q19: =IFERROR(__xludf.DUMMYFUNCTION("""COMPUTED_VALUE"""),0.0) -> 0 | R19: =IFERROR(__xludf.DUMMYFUNCTION("""COMPUTED_VALUE"""),0.0) -> 0 | S19: =IFERROR(__xludf.DUMMYFUNCTION("""COMPUTED_VALUE"""),0.0) -> 0 | T19: =IFERROR(__xludf.DUMMYFUNCTION("""COMPUTED_VALUE"""),0.0) -> 0 | U19: =IFERROR(__xludf.DUMMYFUNCTION("""COMPUTED_VALUE"""),1500.0) -> 1500 | V19: =IFERROR(__xludf.DUMMYFUNCTION("""COMPUTED_VALUE"""),500.0) -> 500 | W19: =IFERROR(__xludf.DUMMYFUNCTION("""COMPUTED_VALUE"""),15347.0) -> 15347
B20: Anas | C20: 340 | D20: LYD | E20: Money Out | H20: بضاعه | L20: =IFERROR(__xludf.DUMMYFUNCTION("""COMPUTED_VALUE"""),"2025-05") -> 2025-05 | M20: =IFERROR(__xludf.DUMMYFUNCTION("""COMPUTED_VALUE"""),8426.0) -> 8426 | N20: =IFERROR(__xludf.DUMMYFUNCTION("""COMPUTED_VALUE"""),1157.0) -> 1157 | O20: =IFERROR(__xludf.DUMMYFUNCTION("""COMPUTED_VALUE"""),0.0) -> 0 | P20: =IFERROR(__xludf.DUMMYFUNCTION("""COMPUTED_VALUE"""),7269.0) -> 7269 | Q20: =IFERROR(__xludf.DUMMYFUNCTION("""COMPUTED_VALUE"""),0.0) -> 0 | R20: =IFERROR(__xludf.DUMMYFUNCTION("""COMPUTED_VALUE"""),0.0) -> 0 | S20: =IFERROR(__xludf.DUMMYFUNCTION("""COMPUTED_VALUE"""),0.0) -> 0 | T20: =IFERROR(__xludf.DUMMYFUNCTION("""COMPUTED_VALUE"""),0.0) -> 0 | U20: =IFERROR(__xludf.DUMMYFUNCTION("""COMPUTED_VALUE"""),0.0) -> 0 | V20: =IFERROR(__xludf.DUMMYFUNCTION("""COMPUTED_VALUE"""),1500.0) -> 1500 | W20: =IFERROR(__xludf.DUMMYFUNCTION("""COMPUTED_VALUE"""),6926.0) -> 6926
B21: Anas | C21: 885 | D21: LYD | E21: Money Out | H21: طباعه وتصميم | L21: =IFERROR(__xludf.DUMMYFUNCTION("""COMPUTED_VALUE"""),"2025-06") -> 2025-06 | M21: =IFERROR(__xludf.DUMMYFUNCTION("""COMPUTED_VALUE"""),18609.0) -> 18609 | N21: =IFERROR(__xludf.DUMMYFUNCTION("""COMPUTED_VALUE"""),11413.0) -> 11413 | O21: =IFERROR(__xludf.DUMMYFUNCTION("""COMPUTED_VALUE"""),0.0) -> 0 | P21: =IFERROR(__xludf.DUMMYFUNCTION("""COMPUTED_VALUE"""),7196.0) -> 7196 | Q21: =IFERROR(__xludf.DUMMYFUNCTION("""COMPUTED_VALUE"""),0.0) -> 0 | R21: =IFERROR(__xludf.DUMMYFUNCTION("""COMPUTED_VALUE"""),0.0) -> 0 | S21: =IFERROR(__xludf.DUMMYFUNCTION("""COMPUTED_VALUE"""),0.0) -> 0 | T21: =IFERROR(__xludf.DUMMYFUNCTION("""COMPUTED_VALUE"""),0.0) -> 0 | U21: =IFERROR(__xludf.DUMMYFUNCTION("""COMPUTED_VALUE"""),3000.0) -> 3000 | V21: =IFERROR(__xludf.DUMMYFUNCTION("""COMPUTED_VALUE"""),1500.0) -> 1500 | W21: =IFERROR(__xludf.DUMMYFUNCTION("""COMPUTED_VALUE"""),17109.0) -> 17109
B22: Anas | C22: 702 | D22: LYD | E22: Money Out | H22: بضاعه | L22: =IFERROR(__xludf.DUMMYFUNCTION("""COMPUTED_VALUE"""),"2025-07") -> 2025-07 | M22: =IFERROR(__xludf.DUMMYFUNCTION("""COMPUTED_VALUE"""),19450.0) -> 19450 | N22: =IFERROR(__xludf.DUMMYFUNCTION("""COMPUTED_VALUE"""),8693.0) -> 8693 | O22: =IFERROR(__xludf.DUMMYFUNCTION("""COMPUTED_VALUE"""),0.0) -> 0 | P22: =IFERROR(__xludf.DUMMYFUNCTION("""COMPUTED_VALUE"""),7434.0) -> 7434 | Q22: =IFERROR(__xludf.DUMMYFUNCTION("""COMPUTED_VALUE"""),0.0) -> 0 | R22: =IFERROR(__xludf.DUMMYFUNCTION("""COMPUTED_VALUE"""),0.0) -> 0 | S22: =IFERROR(__xludf.DUMMYFUNCTION("""COMPUTED_VALUE"""),3323.0) -> 3323 | T22: =IFERROR(__xludf.DUMMYFUNCTION("""COMPUTED_VALUE"""),0.0) -> 0 | U22: =IFERROR(__xludf.DUMMYFUNCTION("""COMPUTED_VALUE"""),3000.0) -> 3000 | V22: =IFERROR(__xludf.DUMMYFUNCTION("""COMPUTED_VALUE"""),1500.0) -> 1500 | W22: =IFERROR(__xludf.DUMMYFUNCTION("""COMPUTED_VALUE"""),17950.0) -> 17950
B23: Anas | C23: 5 | D23: $ | E23: Money Out | H23: سعر الشحن من شاهين شحنة الخيط | L23: =IFERROR(__xludf.DUMMYFUNCTION("""COMPUTED_VALUE"""),"2025-08") -> 2025-08 | M23: =IFERROR(__xludf.DUMMYFUNCTION("""COMPUTED_VALUE"""),19750.0) -> 19750 | N23: =IFERROR(__xludf.DUMMYFUNCTION("""COMPUTED_VALUE"""),8500.0) -> 8500 | O23: =IFERROR(__xludf.DUMMYFUNCTION("""COMPUTED_VALUE"""),0.0) -> 0 | P23: =IFERROR(__xludf.DUMMYFUNCTION("""COMPUTED_VALUE"""),5622.0) -> 5622 | Q23: =IFERROR(__xludf.DUMMYFUNCTION("""COMPUTED_VALUE"""),0.0) -> 0 | R23: =IFERROR(__xludf.DUMMYFUNCTION("""COMPUTED_VALUE"""),0.0) -> 0 | S23: =IFERROR(__xludf.DUMMYFUNCTION("""COMPUTED_VALUE"""),5628.0) -> 5628 | T23: =IFERROR(__xludf.DUMMYFUNCTION("""COMPUTED_VALUE"""),0.0) -> 0 | U23: =IFERROR(__xludf.DUMMYFUNCTION("""COMPUTED_VALUE"""),0.0) -> 0 | V23: =IFERROR(__xludf.DUMMYFUNCTION("""COMPUTED_VALUE"""),1500.0) -> 1500 | W23: =IFERROR(__xludf.DUMMYFUNCTION("""COMPUTED_VALUE"""),18250.0) -> 18250
B24: Anas | C24: 59.5 | D24: LYD | E24: Money Out | H24: بضاعه (مياه) | L24: =IFERROR(__xludf.DUMMYFUNCTION("""COMPUTED_VALUE"""),"2025-09") -> 2025-09 | M24: =IFERROR(__xludf.DUMMYFUNCTION("""COMPUTED_VALUE"""),12927.0) -> 12927 | N24: =IFERROR(__xludf.DUMMYFUNCTION("""COMPUTED_VALUE"""),5884.0) -> 5884 | O24: =IFERROR(__xludf.DUMMYFUNCTION("""COMPUTED_VALUE"""),0.0) -> 0 | P24: =IFERROR(__xludf.DUMMYFUNCTION("""COMPUTED_VALUE"""),3091.0) -> 3091 | Q24: =IFERROR(__xludf.DUMMYFUNCTION("""COMPUTED_VALUE"""),0.0) -> 0 | R24: =IFERROR(__xludf.DUMMYFUNCTION("""COMPUTED_VALUE"""),0.0) -> 0 | S24: =IFERROR(__xludf.DUMMYFUNCTION("""COMPUTED_VALUE"""),3952.0) -> 3952 | T24: =IFERROR(__xludf.DUMMYFUNCTION("""COMPUTED_VALUE"""),0.0) -> 0 | U24: =IFERROR(__xludf.DUMMYFUNCTION("""COMPUTED_VALUE"""),10000.0) -> 10000 | V24: =IFERROR(__xludf.DUMMYFUNCTION("""COMPUTED_VALUE"""),1500.0) -> 1500 | W24: =IFERROR(__xludf.DUMMYFUNCTION("""COMPUTED_VALUE"""),11427.0) -> 11427
B25: Anas | C25: 60 | D25: LYD | E25: Money Out | H25: بضاعه (مياه) | L25: =IFERROR(__xludf.DUMMYFUNCTION("""COMPUTED_VALUE"""),"2025-10") -> 2025-10 | M25: =IFERROR(__xludf.DUMMYFUNCTION("""COMPUTED_VALUE"""),16451.0) -> 16451 | N25: =IFERROR(__xludf.DUMMYFUNCTION("""COMPUTED_VALUE"""),6696.0) -> 6696 | O25: =IFERROR(__xludf.DUMMYFUNCTION("""COMPUTED_VALUE"""),0.0) -> 0 | P25: =IFERROR(__xludf.DUMMYFUNCTION("""COMPUTED_VALUE"""),4636.0) -> 4636 | Q25: =IFERROR(__xludf.DUMMYFUNCTION("""COMPUTED_VALUE"""),0.0) -> 0 | R25: =IFERROR(__xludf.DUMMYFUNCTION("""COMPUTED_VALUE"""),0.0) -> 0 | S25: =IFERROR(__xludf.DUMMYFUNCTION("""COMPUTED_VALUE"""),5119.0) -> 5119 | T25: =IFERROR(__xludf.DUMMYFUNCTION("""COMPUTED_VALUE"""),0.0) -> 0 | U25: =IFERROR(__xludf.DUMMYFUNCTION("""COMPUTED_VALUE"""),0.0) -> 0 | V25: =IFERROR(__xludf.DUMMYFUNCTION("""COMPUTED_VALUE"""),1500.0) -> 1500 | W25: =IFERROR(__xludf.DUMMYFUNCTION("""COMPUTED_VALUE"""),14951.0) -> 14951
B26: Anas | C26: 15 | D26: LYD | E26: Money Out | H26: كرت LTT | L26: =IFERROR(__xludf.DUMMYFUNCTION("""COMPUTED_VALUE"""),"2025-11") -> 2025-11 | M26: =IFERROR(__xludf.DUMMYFUNCTION("""COMPUTED_VALUE"""),13267.0) -> 13267 | N26: =IFERROR(__xludf.DUMMYFUNCTION("""COMPUTED_VALUE"""),5090.0) -> 5090 | O26: =IFERROR(__xludf.DUMMYFUNCTION("""COMPUTED_VALUE"""),0.0) -> 0 | P26: =IFERROR(__xludf.DUMMYFUNCTION("""COMPUTED_VALUE"""),3893.0) -> 3893 | Q26: =IFERROR(__xludf.DUMMYFUNCTION("""COMPUTED_VALUE"""),0.0) -> 0 | R26: =IFERROR(__xludf.DUMMYFUNCTION("""COMPUTED_VALUE"""),0.0) -> 0 | S26: =IFERROR(__xludf.DUMMYFUNCTION("""COMPUTED_VALUE"""),4284.0) -> 4284 | T26: =IFERROR(__xludf.DUMMYFUNCTION("""COMPUTED_VALUE"""),0.0) -> 0 | U26: =IFERROR(__xludf.DUMMYFUNCTION("""COMPUTED_VALUE"""),0.0) -> 0 | V26: =IFERROR(__xludf.DUMMYFUNCTION("""COMPUTED_VALUE"""),1500.0) -> 1500 | W26: =IFERROR(__xludf.DUMMYFUNCTION("""COMPUTED_VALUE"""),11767.0) -> 11767
B27: Snacky | C27: 1882 | D27: LYD | E27: Money Out | F27: Product Restocking | H27: بضاعه | L27: =IFERROR(__xludf.DUMMYFUNCTION("""COMPUTED_VALUE"""),"2025-12") -> 2025-12 | M27: =IFERROR(__xludf.DUMMYFUNCTION("""COMPUTED_VALUE"""),17828.0) -> 17828 | N27: =IFERROR(__xludf.DUMMYFUNCTION("""COMPUTED_VALUE"""),8092.0) -> 8092 | O27: =IFERROR(__xludf.DUMMYFUNCTION("""COMPUTED_VALUE"""),0.0) -> 0 | P27: =IFERROR(__xludf.DUMMYFUNCTION("""COMPUTED_VALUE"""),4621.0) -> 4621 | Q27: =IFERROR(__xludf.DUMMYFUNCTION("""COMPUTED_VALUE"""),0.0) -> 0 | R27: =IFERROR(__xludf.DUMMYFUNCTION("""COMPUTED_VALUE"""),0.0) -> 0 | S27: =IFERROR(__xludf.DUMMYFUNCTION("""COMPUTED_VALUE"""),5115.0) -> 5115 | T27: =IFERROR(__xludf.DUMMYFUNCTION("""COMPUTED_VALUE"""),0.0) -> 0 | U27: =IFERROR(__xludf.DUMMYFUNCTION("""COMPUTED_VALUE"""),0.0) -> 0 | V27: =IFERROR(__xludf.DUMMYFUNCTION("""COMPUTED_VALUE"""),1500.0) -> 1500 | W27: =IFERROR(__xludf.DUMMYFUNCTION("""COMPUTED_VALUE"""),16328.0) -> 16328
B28: Anas | C28: 61 | D28: LYD | E28: Money Out | F28: Product Restocking | H28: بضاعه (مياه) | L28: =IFERROR(__xludf.DUMMYFUNCTION("""COMPUTED_VALUE"""),"2026-01") -> 2026-01 | M28: =IFERROR(__xludf.DUMMYFUNCTION("""COMPUTED_VALUE"""),21248.0) -> 21248 | N28: =IFERROR(__xludf.DUMMYFUNCTION("""COMPUTED_VALUE"""),10344.0) -> 10344 | O28: =IFERROR(__xludf.DUMMYFUNCTION("""COMPUTED_VALUE"""),0.0) -> 0 | P28: =IFERROR(__xludf.DUMMYFUNCTION("""COMPUTED_VALUE"""),2894.0) -> 2894 | Q28: =IFERROR(__xludf.DUMMYFUNCTION("""COMPUTED_VALUE"""),0.0) -> 0 | R28: =IFERROR(__xludf.DUMMYFUNCTION("""COMPUTED_VALUE"""),0.0) -> 0 | S28: =IFERROR(__xludf.DUMMYFUNCTION("""COMPUTED_VALUE"""),4992.0) -> 4992 | T28: =IFERROR(__xludf.DUMMYFUNCTION("""COMPUTED_VALUE"""),3018.0) -> 3018 | U28: =IFERROR(__xludf.DUMMYFUNCTION("""COMPUTED_VALUE"""),0.0) -> 0 | V28: =IFERROR(__xludf.DUMMYFUNCTION("""COMPUTED_VALUE"""),1500.0) -> 1500 | W28: =IFERROR(__xludf.DUMMYFUNCTION("""COMPUTED_VALUE"""),19748.0) -> 19748
A29: 45634 | B29: Snacky | C29: 1943 | D29: LYD | E29: Money In | F29: Revenue | G29: deplomacyMall | H29: قيمة اول 5 ايام | L29: =IFERROR(__xludf.DUMMYFUNCTION("""COMPUTED_VALUE"""),"2026-02") -> 2026-02 | M29: =IFERROR(__xludf.DUMMYFUNCTION("""COMPUTED_VALUE"""),25346.0) -> 25346 | N29: =IFERROR(__xludf.DUMMYFUNCTION("""COMPUTED_VALUE"""),7474.0) -> 7474 | O29: =IFERROR(__xludf.DUMMYFUNCTION("""COMPUTED_VALUE"""),4153.0) -> 4153 | P29: =IFERROR(__xludf.DUMMYFUNCTION("""COMPUTED_VALUE"""),2387.0) -> 2387 | Q29: =IFERROR(__xludf.DUMMYFUNCTION("""COMPUTED_VALUE"""),3577.0) -> 3577 | R29: =IFERROR(__xludf.DUMMYFUNCTION("""COMPUTED_VALUE"""),0.0) -> 0 | S29: =IFERROR(__xludf.DUMMYFUNCTION("""COMPUTED_VALUE"""),4241.0) -> 4241 | T29: =IFERROR(__xludf.DUMMYFUNCTION("""COMPUTED_VALUE"""),3514.0) -> 3514 | U29: =IFERROR(__xludf.DUMMYFUNCTION("""COMPUTED_VALUE"""),6000.0) -> 6000 | V29: =IFERROR(__xludf.DUMMYFUNCTION("""COMPUTED_VALUE"""),2300.0) -> 2300 | W29: =IFERROR(__xludf.DUMMYFUNCTION("""COMPUTED_VALUE"""),23046.0) -> 23046
A30: 45641 | B30: Snacky | C30: 779 | D30: LYD | E30: Money In | F30: Revenue | G30: deplomacyMall | L30: =IFERROR(__xludf.DUMMYFUNCTION("""COMPUTED_VALUE"""),"2026-03") -> 2026-03 | M30: =IFERROR(__xludf.DUMMYFUNCTION("""COMPUTED_VALUE"""),35177.0) -> 35177 | N30: =IFERROR(__xludf.DUMMYFUNCTION("""COMPUTED_VALUE"""),14346.0) -> 14346 | O30: =IFERROR(__xludf.DUMMYFUNCTION("""COMPUTED_VALUE"""),6583.0) -> 6583 | P30: =IFERROR(__xludf.DUMMYFUNCTION("""COMPUTED_VALUE"""),8453.0) -> 8453 | Q30: =IFERROR(__xludf.DUMMYFUNCTION("""COMPUTED_VALUE"""),1081.0) -> 1081 | R30: =IFERROR(__xludf.DUMMYFUNCTION("""COMPUTED_VALUE"""),0.0) -> 0 | S30: =IFERROR(__xludf.DUMMYFUNCTION("""COMPUTED_VALUE"""),4714.0) -> 4714 | T30: =IFERROR(__xludf.DUMMYFUNCTION("""COMPUTED_VALUE"""),0.0) -> 0 | U30: =IFERROR(__xludf.DUMMYFUNCTION("""COMPUTED_VALUE"""),0.0) -> 0 | V30: =IFERROR(__xludf.DUMMYFUNCTION("""COMPUTED_VALUE"""),2300.0) -> 2300 | W30: =IFERROR(__xludf.DUMMYFUNCTION("""COMPUTED_VALUE"""),32877.0) -> 32877
A31: 45644 | B31: Snacky | C31: 20 | D31: LYD | E31: Money Out | F31: Product Restocking | H31: بضاعه (مياه) | L31: =IFERROR(__xludf.DUMMYFUNCTION("""COMPUTED_VALUE"""),"2026-04") -> 2026-04 | M31: =IFERROR(__xludf.DUMMYFUNCTION("""COMPUTED_VALUE"""),46084.0) -> 46084 | N31: =IFERROR(__xludf.DUMMYFUNCTION("""COMPUTED_VALUE"""),7699.0) -> 7699 | O31: =IFERROR(__xludf.DUMMYFUNCTION("""COMPUTED_VALUE"""),5518.0) -> 5518 | P31: =IFERROR(__xludf.DUMMYFUNCTION("""COMPUTED_VALUE"""),0.0) -> 0 | Q31: =IFERROR(__xludf.DUMMYFUNCTION("""COMPUTED_VALUE"""),8263.0) -> 8263 | R31: =IFERROR(__xludf.DUMMYFUNCTION("""COMPUTED_VALUE"""),9830.0) -> 9830 | S31: =IFERROR(__xludf.DUMMYFUNCTION("""COMPUTED_VALUE"""),5871.0) -> 5871 | T31: =IFERROR(__xludf.DUMMYFUNCTION("""COMPUTED_VALUE"""),8903.0) -> 8903 | U31: =IFERROR(__xludf.DUMMYFUNCTION("""COMPUTED_VALUE"""),0.0) -> 0 | V31: =IFERROR(__xludf.DUMMYFUNCTION("""COMPUTED_VALUE"""),1800.0) -> 1800 | W31: =IFERROR(__xludf.DUMMYFUNCTION("""COMPUTED_VALUE"""),44284.0) -> 44284
A32: 45523 | B32: Snacky | C32: 46 | D32: LYD | E32: Money Out | H32: مياه + لصقة دبل فيس
A33: 45524 | B33: Snacky | C33: 1225 | D33: LYD | E33: Money In | F33: Revenue | G33: deplomacyMall
A34: 45525 | B34: Snacky | C34: 180 | D34: LYD | E34: Money Out | H34: طباعة توربو للايت بوكس
A35: 45525 | B35: Snacky | C35: 2500 | D35: LYD | E35: Money In | F35: ads | H35: دعاية توربو ( من نص 9 الى نص 12)
A36: 45528 | B36: Snacky | C36: 50 | D36: LYD | E36: Money Out
A37: 45528 | B37: Anas | C37: 50 | D37: LYD | E37: Money In
A38: 45528 | B38: Snacky | C38: 40 | D38: LYD | E38: Money Out | F38: Product Restocking | H38: بضاعه (مياه)
A39: 45530 | B39: Snacky | C39: 1140 | D39: LYD | E39: Money Out | F39: Product Restocking | H39: بضاعه
A40: 45530 | B40: Snacky | C40: 900 | D40: LYD | E40: Money In | F40: Revenue | G40: deplomacyMall
A41: 45533 | B41: Snacky | C41: 60 | D41: LYD | E41: Money Out | F41: Product Restocking | H41: بضاعه (مياه)
A42: 45535 | B42: Snacky | C42: 18 | D42: LYD | E42: Money Out | F42: Product Restocking | H42: بضاعه (مياه)
...

Sheet Ahmed
A1: Date | B1: البضاعه | C1: مرتب | D1: Column 4 | E1: Column 5
A3: 45962 | C3: 1400
A4: 45992
A5: 46053 | C5: 1400
A6: 46081 | C6: 1600
A7: 46112 | C7: 1500
A8: 46142 | C8: 750

Sheet Lists
A1: Bucket | C1: Type | D1: Bucket
A2: Inventory | C2: Revenue | D2: Inflow
A3: Operations | C3: ads | D3: Inflow
A4: Fixed Costs | C4: Product Restocking | D4: Inventory
A5: Profit | C5: Ahmed | D5: Operations
C6: Anas | D6: Owner Draw
C7: Rent | D7: Fixed Costs
C8: charity | D8: Operations
C9: Transport | D9: Operations
C10: Storage | D10: Fixed Costs

Sheet Txn_Control
A1: =IFERROR(__xludf.DUMMYFUNCTION("FILTER(Transactions!A2:A1000,Transactions!A2:A1000<>"""")"),"Date") -> Date | B1: =IFERROR(__xludf.DUMMYFUNCTION("FILTER(Transactions!C2:C1000,Transactions!A2:A1000<>"""")"),"Transaction") -> Transaction | C1: =IFERROR(__xludf.DUMMYFUNCTION("FILTER(Transactions!E2:E1000,Transactions!A2:A1000<>"""")"),"Money Flow") -> Money Flow | D1: =IFERROR(__xludf.DUMMYFUNCTION("FILTER(Transactions!F2:F1000,Transactions!A2:A1000<>"""")"),"Transaction Type") -> Transaction Type | E1: =IFERROR(__xludf.DUMMYFUNCTION("FILTER(Transactions!G2:G1000,Transactions!A2:A1000<>"""")"),"Location") -> Location | F1: =IFERROR(__xludf.DUMMYFUNCTION("FILTER(Transactions!H2:H1000,Transactions!A2:A1000<>"""")"),"Transaction Description") -> Transaction Description | G1: Signed Amount | H1: Auto Bucket | I1: Bucket Override | J1: Final Bucket
A2: =IFERROR(__xludf.DUMMYFUNCTION("""COMPUTED_VALUE"""),45634.0) -> 45634 | B2: =IFERROR(__xludf.DUMMYFUNCTION("""COMPUTED_VALUE"""),1943.0) -> 1943 | C2: =IFERROR(__xludf.DUMMYFUNCTION("""COMPUTED_VALUE"""),"Money In") -> Money In | D2: =IFERROR(__xludf.DUMMYFUNCTION("""COMPUTED_VALUE"""),"Revenue") -> Revenue | E2: =IFERROR(__xludf.DUMMYFUNCTION("""COMPUTED_VALUE"""),"deplomacyMall") -> deplomacyMall | F2: =IFERROR(__xludf.DUMMYFUNCTION("""COMPUTED_VALUE"""),"قيمة اول 5 ايام") -> قيمة اول 5 ايام | G2: {=IF(A2:A1000="","",IF(C2:C1000="Money In",B2:B1000,-B2:B1000))} -> 1943 | H2: {=IF(A2:A1000="","",IFERROR(VLOOKUP(D2:D1000,Lists!C:D,2,FALSE),"Review"))} -> Inflow | J2: {=IF(A2:A1000="","",IF(I2:I1000<>"",I2:I1000,H2:H1000))} -> Inflow
A3: =IFERROR(__xludf.DUMMYFUNCTION("""COMPUTED_VALUE"""),45641.0) -> 45641 | B3: =IFERROR(__xludf.DUMMYFUNCTION("""COMPUTED_VALUE"""),779.0) -> 779 | C3: =IFERROR(__xludf.DUMMYFUNCTION("""COMPUTED_VALUE"""),"Money In") -> Money In | D3: =IFERROR(__xludf.DUMMYFUNCTION("""COMPUTED_VALUE"""),"Revenue") -> Revenue | E3: =IFERROR(__xludf.DUMMYFUNCTION("""COMPUTED_VALUE"""),"deplomacyMall") -> deplomacyMall | G3: 779 | H3: Inflow | J3: Inflow
A4: =IFERROR(__xludf.DUMMYFUNCTION("""COMPUTED_VALUE"""),45644.0) -> 45644 | B4: =IFERROR(__xludf.DUMMYFUNCTION("""COMPUTED_VALUE"""),20.0) -> 20 | C4: =IFERROR(__xludf.DUMMYFUNCTION("""COMPUTED_VALUE"""),"Money Out") -> Money Out | D4: =IFERROR(__xludf.DUMMYFUNCTION("""COMPUTED_VALUE"""),"Product Restocking") -> Product Restocking | F4: =IFERROR(__xludf.DUMMYFUNCTION("""COMPUTED_VALUE"""),"بضاعه (مياه)") -> بضاعه (مياه) | G4: -20 | H4: Inventory | J4: Inventory
A5: =IFERROR(__xludf.DUMMYFUNCTION("""COMPUTED_VALUE"""),45523.0) -> 45523 | B5: =IFERROR(__xludf.DUMMYFUNCTION("""COMPUTED_VALUE"""),46.0) -> 46 | C5: =IFERROR(__xludf.DUMMYFUNCTION("""COMPUTED_VALUE"""),"Money Out") -> Money Out | F5: =IFERROR(__xludf.DUMMYFUNCTION("""COMPUTED_VALUE"""),"مياه + لصقة دبل فيس") -> مياه + لصقة دبل فيس | G5: -46 | H5: Review | J5: Review
A6: =IFERROR(__xludf.DUMMYFUNCTION("""COMPUTED_VALUE"""),45524.0) -> 45524 | B6: =IFERROR(__xludf.DUMMYFUNCTION("""COMPUTED_VALUE"""),1225.0) -> 1225 | C6: =IFERROR(__xludf.DUMMYFUNCTION("""COMPUTED_VALUE"""),"Money In") -> Money In | D6: =IFERROR(__xludf.DUMMYFUNCTION("""COMPUTED_VALUE"""),"Revenue") -> Revenue | E6: =IFERROR(__xludf.DUMMYFUNCTION("""COMPUTED_VALUE"""),"deplomacyMall") -> deplomacyMall | G6: 1225 | H6: Inflow | J6: Inflow
A7: =IFERROR(__xludf.DUMMYFUNCTION("""COMPUTED_VALUE"""),45525.0) -> 45525 | B7: =IFERROR(__xludf.DUMMYFUNCTION("""COMPUTED_VALUE"""),180.0) -> 180 | C7: =IFERROR(__xludf.DUMMYFUNCTION("""COMPUTED_VALUE"""),"Money Out") -> Money Out | F7: =IFERROR(__xludf.DUMMYFUNCTION("""COMPUTED_VALUE"""),"طباعة توربو للايت بوكس") -> طباعة توربو للايت بوكس | G7: -180 | H7: Review | J7: Review
A8: =IFERROR(__xludf.DUMMYFUNCTION("""COMPUTED_VALUE"""),45525.0) -> 45525 | B8: =IFERROR(__xludf.DUMMYFUNCTION("""COMPUTED_VALUE"""),2500.0) -> 2500 | C8: =IFERROR(__xludf.DUMMYFUNCTION("""COMPUTED_VALUE"""),"Money In") -> Money In | D8: =IFERROR(__xludf.DUMMYFUNCTION("""COMPUTED_VALUE"""),"ads") -> ads | F8: =IFERROR(__xludf.DUMMYFUNCTION("""COMPUTED_VALUE""")," دعاية توربو ( من نص 9 الى نص 12)") -> دعاية توربو ( من نص 9 الى نص 12) | G8: 2500 | H8: Inflow | J8: Inflow
A9: =IFERROR(__xludf.DUMMYFUNCTION("""COMPUTED_VALUE"""),45528.0) -> 45528 | B9: =IFERROR(__xludf.DUMMYFUNCTION("""COMPUTED_VALUE"""),50.0) -> 50 | C9: =IFERROR(__xludf.DUMMYFUNCTION("""COMPUTED_VALUE"""),"Money Out") -> Money Out | G9: -50 | H9: Review | J9: Review
A10: =IFERROR(__xludf.DUMMYFUNCTION("""COMPUTED_VALUE"""),45528.0) -> 45528 | B10: =IFERROR(__xludf.DUMMYFUNCTION("""COMPUTED_VALUE"""),50.0) -> 50 | C10: =IFERROR(__xludf.DUMMYFUNCTION("""COMPUTED_VALUE"""),"Money In") -> Money In | G10: 50 | H10: Review | J10: Review
A11: =IFERROR(__xludf.DUMMYFUNCTION("""COMPUTED_VALUE"""),45528.0) -> 45528 | B11: =IFERROR(__xludf.DUMMYFUNCTION("""COMPUTED_VALUE"""),40.0) -> 40 | C11: =IFERROR(__xludf.DUMMYFUNCTION("""COMPUTED_VALUE"""),"Money Out") -> Money Out | D11: =IFERROR(__xludf.DUMMYFUNCTION("""COMPUTED_VALUE"""),"Product Restocking") -> Product Restocking | F11: =IFERROR(__xludf.DUMMYFUNCTION("""COMPUTED_VALUE"""),"بضاعه (مياه)") -> بضاعه (مياه) | G11: -40 | H11: Inventory | J11: Inventory
A12: =IFERROR(__xludf.DUMMYFUNCTION("""COMPUTED_VALUE"""),45530.0) -> 45530 | B12: =IFERROR(__xludf.DUMMYFUNCTION("""COMPUTED_VALUE"""),1140.0) -> 1140 | C12: =IFERROR(__xludf.DUMMYFUNCTION("""COMPUTED_VALUE"""),"Money Out") -> Money Out | D12: =IFERROR(__xludf.DUMMYFUNCTION("""COMPUTED_VALUE"""),"Product Restocking") -> Product Restocking | F12: =IFERROR(__xludf.DUMMYFUNCTION("""COMPUTED_VALUE"""),"بضاعه ") -> بضاعه | G12: -1140 | H12: Inventory | J12: Inventory
A13: =IFERROR(__xludf.DUMMYFUNCTION("""COMPUTED_VALUE"""),45530.0) -> 45530 | B13: =IFERROR(__xludf.DUMMYFUNCTION("""COMPUTED_VALUE"""),900.0) -> 900 | C13: =IFERROR(__xludf.DUMMYFUNCTION("""COMPUTED_VALUE"""),"Money In") -> Money In | D13: =IFERROR(__xludf.DUMMYFUNCTION("""COMPUTED_VALUE"""),"Revenue") -> Revenue | E13: =IFERROR(__xludf.DUMMYFUNCTION("""COMPUTED_VALUE"""),"deplomacyMall") -> deplomacyMall | G13: 900 | H13: Inflow | J13: Inflow
A14: =IFERROR(__xludf.DUMMYFUNCTION("""COMPUTED_VALUE"""),45533.0) -> 45533 | B14: =IFERROR(__xludf.DUMMYFUNCTION("""COMPUTED_VALUE"""),60.0) -> 60 | C14: =IFERROR(__xludf.DUMMYFUNCTION("""COMPUTED_VALUE"""),"Money Out") -> Money Out | D14: =IFERROR(__xludf.DUMMYFUNCTION("""COMPUTED_VALUE"""),"Product Restocking") -> Product Restocking | F14: =IFERROR(__xludf.DUMMYFUNCTION("""COMPUTED_VALUE"""),"بضاعه (مياه)") -> بضاعه (مياه) | G14: -60 | H14: Inventory | J14: Inventory
A15: =IFERROR(__xludf.DUMMYFUNCTION("""COMPUTED_VALUE"""),45535.0) -> 45535 | B15: =IFERROR(__xludf.DUMMYFUNCTION("""COMPUTED_VALUE"""),18.0) -> 18 | C15: =IFERROR(__xludf.DUMMYFUNCTION("""COMPUTED_VALUE"""),"Money Out") -> Money Out | D15: =IFERROR(__xludf.DUMMYFUNCTION("""COMPUTED_VALUE"""),"Product Restocking") -> Product Restocking | F15: =IFERROR(__xludf.DUMMYFUNCTION("""COMPUTED_VALUE"""),"بضاعه (مياه)") -> بضاعه (مياه) | G15: -18 | H15: Inventory | J15: Inventory
A16: =IFERROR(__xludf.DUMMYFUNCTION("""COMPUTED_VALUE"""),45535.0) -> 45535 | B16: =IFERROR(__xludf.DUMMYFUNCTION("""COMPUTED_VALUE"""),1158.0) -> 1158 | C16: =IFERROR(__xludf.DUMMYFUNCTION("""COMPUTED_VALUE"""),"Money In") -> Money In | D16: =IFERROR(__xludf.DUMMYFUNCTION("""COMPUTED_VALUE"""),"Revenue") -> Revenue | E16: =IFERROR(__xludf.DUMMYFUNCTION("""COMPUTED_VALUE"""),"deplomacyMall") -> deplomacyMall | G16: 1158 | H16: Inflow | J16: Inflow
A17: =IFERROR(__xludf.DUMMYFUNCTION("""COMPUTED_VALUE"""),45535.0) -> 45535 | B17: =IFERROR(__xludf.DUMMYFUNCTION("""COMPUTED_VALUE"""),15.0) -> 15 | C17: =IFERROR(__xludf.DUMMYFUNCTION("""COMPUTED_VALUE"""),"Money In") -> Money In | G17: 15 | H17: Review | J17: Review
A18: =IFERROR(__xludf.DUMMYFUNCTION("""COMPUTED_VALUE"""),45535.0) -> 45535 | B18: =IFERROR(__xludf.DUMMYFUNCTION("""COMPUTED_VALUE"""),15.0) -> 15 | C18: =IFERROR(__xludf.DUMMYFUNCTION("""COMPUTED_VALUE"""),"Money Out") -> Money Out | G18: -15 | H18: Review | J18: Review
A19: =IFERROR(__xludf.DUMMYFUNCTION("""COMPUTED_VALUE"""),45536.0) -> 45536 | B19: =IFERROR(__xludf.DUMMYFUNCTION("""COMPUTED_VALUE"""),190.0) -> 190 | C19: =IFERROR(__xludf.DUMMYFUNCTION("""COMPUTED_VALUE"""),"Money Out") -> Money Out | F19: =IFERROR(__xludf.DUMMYFUNCTION("""COMPUTED_VALUE"""),"تعديل الميزانيه") -> تعديل الميزانيه | G19: -190 | H19: Review | J19: Review
A20: =IFERROR(__xludf.DUMMYFUNCTION("""COMPUTED_VALUE"""),45536.0) -> 45536 | B20: =IFERROR(__xludf.DUMMYFUNCTION("""COMPUTED_VALUE"""),827.0) -> 827 | C20: =IFERROR(__xludf.DUMMYFUNCTION("""COMPUTED_VALUE"""),"Money Out") -> Money Out | D20: =IFERROR(__xludf.DUMMYFUNCTION("""COMPUTED_VALUE"""),"Product Restocking") -> Product Restocking | F20: =IFERROR(__xludf.DUMMYFUNCTION("""COMPUTED_VALUE"""),"بضاعه ") -> بضاعه | G20: -827 | H20: Inventory | J20: Inventory
A21: =IFERROR(__xludf.DUMMYFUNCTION("""COMPUTED_VALUE"""),45537.0) -> 45537 | B21: =IFERROR(__xludf.DUMMYFUNCTION("""COMPUTED_VALUE"""),40.0) -> 40 | C21: =IFERROR(__xludf.DUMMYFUNCTION("""COMPUTED_VALUE"""),"Money Out") -> Money Out | D21: =IFERROR(__xludf.DUMMYFUNCTION("""COMPUTED_VALUE"""),"Product Restocking") -> Product Restocking | F21: =IFERROR(__xludf.DUMMYFUNCTION("""COMPUTED_VALUE"""),"بضاعه (مياه)") -> بضاعه (مياه) | G21: -40 | H21: Inventory | J21: Inventory
A22: =IFERROR(__xludf.DUMMYFUNCTION("""COMPUTED_VALUE"""),45539.0) -> 45539 | B22: =IFERROR(__xludf.DUMMYFUNCTION("""COMPUTED_VALUE"""),1082.0) -> 1082 | C22: =IFERROR(__xludf.DUMMYFUNCTION("""COMPUTED_VALUE"""),"Money In") -> Money In | D22: =IFERROR(__xludf.DUMMYFUNCTION("""COMPUTED_VALUE"""),"Revenue") -> Revenue | E22: =IFERROR(__xludf.DUMMYFUNCTION("""COMPUTED_VALUE"""),"deplomacyMall") -> deplomacyMall | G22: 1082 | H22: Inflow | J22: Inflow
A23: =IFERROR(__xludf.DUMMYFUNCTION("""COMPUTED_VALUE"""),45539.0) -> 45539 | B23: =IFERROR(__xludf.DUMMYFUNCTION("""COMPUTED_VALUE"""),40.0) -> 40 | C23: =IFERROR(__xludf.DUMMYFUNCTION("""COMPUTED_VALUE"""),"Money Out") -> Money Out | D23: =IFERROR(__xludf.DUMMYFUNCTION("""COMPUTED_VALUE"""),"Product Restocking") -> Product Restocking | F23: =IFERROR(__xludf.DUMMYFUNCTION("""COMPUTED_VALUE"""),"بضاعه (مياه)") -> بضاعه (مياه) | G23: -40 | H23: Inventory | J23: Inventory
A24: =IFERROR(__xludf.DUMMYFUNCTION("""COMPUTED_VALUE"""),45540.0) -> 45540 | B24: =IFERROR(__xludf.DUMMYFUNCTION("""COMPUTED_VALUE"""),64.0) -> 64 | C24: =IFERROR(__xludf.DUMMYFUNCTION("""COMPUTED_VALUE"""),"Money Out") -> Money Out | D24: =IFERROR(__xludf.DUMMYFUNCTION("""COMPUTED_VALUE"""),"Product Restocking") -> Product Restocking | F24: =IFERROR(__xludf.DUMMYFUNCTION("""COMPUTED_VALUE"""),"بضاعه (مياه)") -> بضاعه (مياه) | G24: -64 | H24: Inventory | J24: Inventory
A25: =IFERROR(__xludf.DUMMYFUNCTION("""COMPUTED_VALUE"""),45542.0) -> 45542 | B25: =IFERROR(__xludf.DUMMYFUNCTION("""COMPUTED_VALUE"""),1574.0) -> 1574 | C25: =IFERROR(__xludf.DUMMYFUNCTION("""COMPUTED_VALUE"""),"Money Out") -> Money Out | D25: =IFERROR(__xludf.DUMMYFUNCTION("""COMPUTED_VALUE"""),"Product Restocking") -> Product Restocking | F25: =IFERROR(__xludf.DUMMYFUNCTION("""COMPUTED_VALUE"""),"بضاعه ") -> بضاعه | G25: -1574 | H25: Inventory | J25: Inventory
A26: =IFERROR(__xludf.DUMMYFUNCTION("""COMPUTED_VALUE"""),45542.0) -> 45542 | B26: =IFERROR(__xludf.DUMMYFUNCTION("""COMPUTED_VALUE"""),20.0) -> 20 | C26: =IFERROR(__xludf.DUMMYFUNCTION("""COMPUTED_VALUE"""),"Money Out") -> Money Out | D26: =IFERROR(__xludf.DUMMYFUNCTION("""COMPUTED_VALUE"""),"Product Restocking") -> Product Restocking | F26: =IFERROR(__xludf.DUMMYFUNCTION("""COMPUTED_VALUE"""),"بضاعه (مياه)") -> بضاعه (مياه) | G26: -20 | H26: Inventory | J26: Inventory
A27: =IFERROR(__xludf.DUMMYFUNCTION("""COMPUTED_VALUE"""),45543.0) -> 45543 | B27: =IFERROR(__xludf.DUMMYFUNCTION("""COMPUTED_VALUE"""),40.0) -> 40 | C27: =IFERROR(__xludf.DUMMYFUNCTION("""COMPUTED_VALUE"""),"Money Out") -> Money Out | D27: =IFERROR(__xludf.DUMMYFUNCTION("""COMPUTED_VALUE"""),"Product Restocking") -> Product Restocking | F27: =IFERROR(__xludf.DUMMYFUNCTION("""COMPUTED_VALUE"""),"بضاعه (مياه)") -> بضاعه (مياه) | G27: -40 | H27: Inventory | J27: Inventory
A28: =IFERROR(__xludf.DUMMYFUNCTION("""COMPUTED_VALUE"""),45544.0) -> 45544 | B28: =IFERROR(__xludf.DUMMYFUNCTION("""COMPUTED_VALUE"""),1896.0) -> 1896 | C28: =IFERROR(__xludf.DUMMYFUNCTION("""COMPUTED_VALUE"""),"Money In") -> Money In | D28: =IFERROR(__xludf.DUMMYFUNCTION("""COMPUTED_VALUE"""),"Revenue") -> Revenue | E28: =IFERROR(__xludf.DUMMYFUNCTION("""COMPUTED_VALUE"""),"deplomacyMall") -> deplomacyMall | G28: 1896 | H28: Inflow | J28: Inflow
A29: =IFERROR(__xludf.DUMMYFUNCTION("""COMPUTED_VALUE"""),45544.0) -> 45544 | B29: =IFERROR(__xludf.DUMMYFUNCTION("""COMPUTED_VALUE"""),40.0) -> 40 | C29: =IFERROR(__xludf.DUMMYFUNCTION("""COMPUTED_VALUE"""),"Money Out") -> Money Out | D29: =IFERROR(__xludf.DUMMYFUNCTION("""COMPUTED_VALUE"""),"Product Restocking") -> Product Restocking | F29: =IFERROR(__xludf.DUMMYFUNCTION("""COMPUTED_VALUE"""),"بضاعه (مياه)") -> بضاعه (مياه) | G29: -40 | H29: Inventory | J29: Inventory
A30: =IFERROR(__xludf.DUMMYFUNCTION("""COMPUTED_VALUE"""),45545.0) -> 45545 | B30: =IFERROR(__xludf.DUMMYFUNCTION("""COMPUTED_VALUE"""),225.0) -> 225 | C30: =IFERROR(__xludf.DUMMYFUNCTION("""COMPUTED_VALUE"""),"Money Out") -> Money Out | D30: =IFERROR(__xludf.DUMMYFUNCTION("""COMPUTED_VALUE"""),"Product Restocking") -> Product Restocking | G30: -225 | H30: Inventory | J30: Inventory
A31: =IFERROR(__xludf.DUMMYFUNCTION("""COMPUTED_VALUE"""),45545.0) -> 45545 | B31: =IFERROR(__xludf.DUMMYFUNCTION("""COMPUTED_VALUE"""),325.0) -> 325 | C31: =IFERROR(__xludf.DUMMYFUNCTION("""COMPUTED_VALUE"""),"Money Out") -> Money Out | D31: =IFERROR(__xludf.DUMMYFUNCTION("""COMPUTED_VALUE"""),"Product Restocking") -> Product Restocking | G31: -325 | H31: Inventory | J31: Inventory
A32: =IFERROR(__xludf.DUMMYFUNCTION("""COMPUTED_VALUE"""),45546.0) -> 45546 | B32: =IFERROR(__xludf.DUMMYFUNCTION("""COMPUTED_VALUE"""),57.75) -> 57.75 | C32: =IFERROR(__xludf.DUMMYFUNCTION("""COMPUTED_VALUE"""),"Money Out") -> Money Out | D32: =IFERROR(__xludf.DUMMYFUNCTION("""COMPUTED_VALUE"""),"Product Restocking") -> Product Restocking | F32: =IFERROR(__xludf.DUMMYFUNCTION("""COMPUTED_VALUE"""),"بضاعه (مياه)") -> بضاعه (مياه) | G32: -57.75 | H32: Inventory | J32: Inventory
A33: =IFERROR(__xludf.DUMMYFUNCTION("""COMPUTED_VALUE"""),45547.0) -> 45547 | B33: =IFERROR(__xludf.DUMMYFUNCTION("""COMPUTED_VALUE"""),1134.0) -> 1134 | C33: =IFERROR(__xludf.DUMMYFUNCTION("""COMPUTED_VALUE"""),"Money In") -> Money In | D33: =IFERROR(__xludf.DUMMYFUNCTION("""COMPUTED_VALUE"""),"Revenue") -> Revenue | E33: =IFERROR(__xludf.DUMMYFUNCTION("""COMPUTED_VALUE"""),"deplomacyMall") -> deplomacyMall | G33: 1134 | H33: Inflow | J33: Inflow
A34: =IFERROR(__xludf.DUMMYFUNCTION("""COMPUTED_VALUE"""),45547.0) -> 45547 | B34: =IFERROR(__xludf.DUMMYFUNCTION("""COMPUTED_VALUE"""),446.0) -> 446 | C34: =IFERROR(__xludf.DUMMYFUNCTION("""COMPUTED_VALUE"""),"Money Out") -> Money Out | D34: =IFERROR(__xludf.DUMMYFUNCTION("""COMPUTED_VALUE"""),"Product Restocking") -> Product Restocking | G34: -446 | H34: Inventory | J34: Inventory
A35: =IFERROR(__xludf.DUMMYFUNCTION("""COMPUTED_VALUE"""),45546.0) -> 45546 | B35: =IFERROR(__xludf.DUMMYFUNCTION("""COMPUTED_VALUE"""),61.0) -> 61 | C35: =IFERROR(__xludf.DUMMYFUNCTION("""COMPUTED_VALUE"""),"Money Out") -> Money Out | D35: =IFERROR(__xludf.DUMMYFUNCTION("""COMPUTED_VALUE"""),"Product Restocking") -> Product Restocking | G35: -61 | H35: Inventory | J35: Inventory
A36: =IFERROR(__xludf.DUMMYFUNCTION("""COMPUTED_VALUE"""),45547.0) -> 45547 | B36: =IFERROR(__xludf.DUMMYFUNCTION("""COMPUTED_VALUE"""),72.0) -> 72 | C36: =IFERROR(__xludf.DUMMYFUNCTION("""COMPUTED_VALUE"""),"Money Out") -> Money Out | D36: =IFERROR(__xludf.DUMMYFUNCTION("""COMPUTED_VALUE"""),"Product Restocking") -> Product Restocking | F36: =IFERROR(__xludf.DUMMYFUNCTION("""COMPUTED_VALUE"""),"بضاعه (مياه)") -> بضاعه (مياه) | G36: -72 | H36: Inventory | J36: Inventory
A37: =IFERROR(__xludf.DUMMYFUNCTION("""COMPUTED_VALUE"""),45549.0) -> 45549 | B37: =IFERROR(__xludf.DUMMYFUNCTION("""COMPUTED_VALUE"""),177.0) -> 177 | C37: =IFERROR(__xludf.DUMMYFUNCTION("""COMPUTED_VALUE"""),"Money Out") -> Money Out | D37: =IFERROR(__xludf.DUMMYFUNCTION("""COMPUTED_VALUE"""),"Product Restocking") -> Product Restocking | G37: -177 | H37: Inventory | J37: Inventory
A38: =IFERROR(__xludf.DUMMYFUNCTION("""COMPUTED_VALUE"""),45550.0) -> 45550 | B38: =IFERROR(__xludf.DUMMYFUNCTION("""COMPUTED_VALUE"""),1280.0) -> 1280 | C38: =IFERROR(__xludf.DUMMYFUNCTION("""COMPUTED_VALUE"""),"Money In") -> Money In | D38: =IFERROR(__xludf.DUMMYFUNCTION("""COMPUTED_VALUE"""),"Revenue") -> Revenue | E38: =IFERROR(__xludf.DUMMYFUNCTION("""COMPUTED_VALUE"""),"deplomacyMall") -> deplomacyMall | G38: 1280 | H38: Inflow | J38: Inflow
A39: =IFERROR(__xludf.DUMMYFUNCTION("""COMPUTED_VALUE"""),45551.0) -> 45551 | B39: =IFERROR(__xludf.DUMMYFUNCTION("""COMPUTED_VALUE"""),72.0) -> 72 | C39: =IFERROR(__xludf.DUMMYFUNCTION("""COMPUTED_VALUE"""),"Money Out") -> Money Out | D39: =IFERROR(__xludf.DUMMYFUNCTION("""COMPUTED_VALUE"""),"Product Restocking") -> Product Restocking | F39: =IFERROR(__xludf.DUMMYFUNCTION("""COMPUTED_VALUE"""),"بضاعه (مياه)") -> بضاعه (مياه) | G39: -72 | H39: Inventory | J39: Inventory
A40: =IFERROR(__xludf.DUMMYFUNCTION("""COMPUTED_VALUE"""),45551.0) -> 45551 | B40: =IFERROR(__xludf.DUMMYFUNCTION("""COMPUTED_VALUE"""),585.0) -> 585 | C40: =IFERROR(__xludf.DUMMYFUNCTION("""COMPUTED_VALUE"""),"Money In") -> Money In | D40: =IFERROR(__xludf.DUMMYFUNCTION("""COMPUTED_VALUE"""),"Revenue") -> Revenue | E40: =IFERROR(__xludf.DUMMYFUNCTION("""COMPUTED_VALUE"""),"deplomacyMall") -> deplomacyMall | G40: 585 | H40: Inflow | J40: Inflow
...

Sheet Cash Control
A1: Control Start Date | B1: 46113
A2: Starting Inventory Balance | B2: 0
A3: Starting Operations Balance | B3: 0
A4: Starting Fixed Costs Balance | B4: 0
A5: Starting Profit Balance | B5: 0
A8: Bucket | B8: Starting Balance | C8: Current Balance | E8: Bucket | F8: This Month | G8: Remaining
A9: Inflow | B9: =$B$2 -> 0 | C9: =SUMIFS(Txn_Control!G:G, Txn_Control!J:J, "Inflow", Txn_Control!A:A, ">="&$B$1) -> 46084 | E9: Inventory | F9: =SUMIFS(Txn_Control!G:G,Txn_Control!J:J,E9,Txn_Control!A:A,">="&EOMONTH(TODAY(),-1)+1,Txn_Control!A:A,"<="&TODAY()) -> -3516 | G9: =C9 -> 46084
A10: Inventory | B10: =$B$3 -> 0 | C10: =SUMIFS(Txn_Control!G:G, Txn_Control!J:J, "Inventory", Txn_Control!A:A, ">="&$B$1) -> -26637 | E10: Operations | F10: =SUMIFS(Txn_Control!G:G,Txn_Control!J:J,E10,Txn_Control!A:A,">="&EOMONTH(TODAY(),-1)+1,Txn_Control!A:A,"<="&TODAY()) -> 0 | G10: =C10 -> -26637
A11: Operations | B11: =$B$4 -> 0 | C11: =SUMIFS(Txn_Control!G:G, Txn_Control!J:J, "Operations", Txn_Control!A:A, ">="&$B$1) -> 0 | E11: Fixed Costs | F11: =SUMIFS(Txn_Control!G:G,Txn_Control!J:J,E11,Txn_Control!A:A,">="&EOMONTH(TODAY(),-1)+1,Txn_Control!A:A,"<="&TODAY()) -> 0 | G11: =C11 -> 0
A12: Fixed Costs | B12: =$B$5 -> 0 | C12: =SUMIFS(Txn_Control!G:G, Txn_Control!J:J, "Fixed Costs", Txn_Control!A:A, ">="&$B$1) -> -3000 | E12: Profit | F12: =SUMIFS(Txn_Control!G:G,Txn_Control!J:J,E12,Txn_Control!A:A,">="&EOMONTH(TODAY(),-1)+1,Txn_Control!A:A,"<="&TODAY()) -> 0 | G12: =C12 -> -3000
A13: Owner Draw | C13: =SUMIFS(Txn_Control!G:G, Txn_Control!J:J, "Owner Draw", Txn_Control!A:A, ">="&$B$1) -> -1430
A15: Real Profit Remaining
B16: =SUM(B17:B20) -> 72721
A17: Bucket | B17: Actual | C17: Target | D17: Status
A18: Inflow | B18: =SUMIFS(Txn_Control!G:G,Txn_Control!J:J,"Inflow",Txn_Control!A:A,">="&$B$1) -> 46084
A19: Inventory | B19: =ABS(SUMIFS(Txn_Control!G:G,Txn_Control!J:J,"Inventory",Txn_Control!A:A,">="&$B$1)) -> 26637 | C19: =B19 * VLOOKUP(A19, Targets!A:B,2, FALSE) -> 13318.5 | D19: =IF(B19 > C19, "OVER", "OK") -> OVER
A20: Operations | B20: =ABS(SUMIFS(Txn_Control!G:G, Txn_Control!J:J, A20, Txn_Control!A:A, ">="&$B$1)) -> 0 | C20: =B20 * VLOOKUP(A20, Targets!A:B,2, FALSE) -> 0 | D20: =IF(B20 > C20, "OVER", "OK") -> OK
A21: Fixed Costs | B21: =ABS(SUMIFS(Txn_Control!G:G,Txn_Control!J:J,"Fixed Costs",Txn_Control!A:A,">="&$B$1)) -> 3000 | C21: =B21 * VLOOKUP(A21, Targets!A:B,2, FALSE) -> 450 | D21: =IF(B21 > C21, "OVER", "OK") -> OVER
A22: Owner Draw | B22: =ABS(SUMIFS(Txn_Control!G:G,Txn_Control!J:J,"Owner Draw",Txn_Control!A:A,">="&$B$1)) -> 1430 | C22: =B22 * VLOOKUP(A22, Targets!A:B,2, FALSE) -> 214.5 | D22: =IF(B22 > C22, "OVER", "OK") -> OVER
A23: Cash Remaining | B23: =B18-B19-B20-B21-B22 -> 15017

Sheet Targets
A1: Bucket | B1: Target %
A2: Inventory | B2: 0.5
A3: Operations | B3: 0.2
A4: Fixed Costs | B4: 0.15
A5: Owner Draw | B5: 0.15

Sheet Places
A1: Date Added | B1: Place Name | C1: Contact Name | D1: Phone Number | E1: Location/Address | F1: Type of Place | G1: Priority | H1: Status | I1: Notes | K1: Date Added | L1: Company name | M1: Product | N1: Phone # | O1: Status | P1: Notes
A2: 45844 | B2: روضة اورانج | C2: اسماء محمد عريبي | D2: 918065207 | E2: السياحية ... سوق القبب حي الوحدة العربية | F2: روضه | G2: Low | H2: Interested | K2: 45848 | L2: مزن الدوليه | M2: مشروب هيلتي كولا | N2: 912207990
A3: 45844 | B3: مدرسة المدارات الدولية | D3: 916957260 | E3: السياحية | F3: مدرسه | G3: Medium | H3: Waiting for Machine | I3: تم موافقتهم ب نسبه 10% من المبيعات ك ايجار | K3: 45850 | L3: غداء الموسم | M3: بطاطا سبدز | N3: 918164242
A4: 45845 | B4: ترانيم (زناته) | C4: احمد | D4: 926760616 | E4: زناته | F4: مركز كورسات | G4: Medium | H4: Interested
A5: 45845 | B5: منارات | C5: احمد | E5: حي الاندلس | F5: مركز كورسات | G5: Medium | H5: Interested
A6: 45846 | B6: المواصفات | C6: ابوبكر شويشين | D6: 912123706 | E6: طريق المطار | F6: مشفى | G6: High | H6: Installed
A7: 45846 | B7: مدرسة الائتلاف الأفضل للتعليم الفرنسي | C7: فرح بن عثمان | D7: 0914712323 0925174633 | E7: خلف مخبز ابونواس | F7: مدرسه | G7: Low | H7: Interested
A8: 45847 | B8: مدرسة سي كوست | C8: عبد السلام رمضان | D8: 928634810 | E8: حي الاندلس, حي دمشق, بقرب جامعة ناصر | F8: مدرسه | G8: High | H8: Installed | I8: تم التفاهم عل 750 شهريا بنائا على 400 طالب
A9: 45850 | B9: الكلية الدولية | C9: نبيل | D9: 911561483 | E9: زناته | F9: مركز كورسات | G9: Low | H9: Follow-Up Later
A10: 45850 | B10: مركز عافية لطب الاسنان | C10: د.ساره الكوحة | D10: 927157091 | E10: 11 يونيو | F10: عياده | G10: Low | H10: Interested
A11: 45850 | B11: مستشفى رويال الطبي | C11: حسين الشاوش | D11: =+218954300044 -> 218954300044 | E11: الزاويه | F11: مستشفى | G11: High | H11: Interested
A12: 45861 | B12: المدرسه الكنديه | D12: 923320534 | E12: السياحيه | F12: مدرسه | G12: Medium | H12: Interested
A13: 45861 | B13: جامعة طرابلس
A14: 45862 | B14: شركة هواوي | C14: علي المقطوف | D14: 925928463 | E14: النوفليين | F14: شركه | G14: Medium | H14: New Lead
A15: 45885 | B15: مختبرالسراي | C15: وليد | D15: 926161208 | E15: حي الاندلس | F15: مختبر | G15: Low | H15: Interested
A16: 45885 | B16: مصحة الاستقلال | C16: محمد حسين احمد | D16: 912124696 | E16: سوق الجمعة | F16: مستشفى | G16: High | H16: Interested
A17: 45889 | B17: كلية ومعهد طرابلس العالي والمتوسط للعلوم الطبية والادارية | C17: د افراح سليم | D17: 910187505 / 0945154518 | E17: فرع عين زارة | F17: كلية | G17: Low | H17: Interested
A18: 45891 | B18: معهد ليبيا التميز العالي للعلوم الطبية | C18: عبدالعزيزالدرهوبي | D18: 926861251 | E18: فرع قصر بن غشير | F18: معهد خصوصي متوسط وعالي | G18: Low | H18: Interested
A19: 45892 | B19: مدرسه لسان العرب | C19: احمد رجب سليمان | D19: 916436072 | E19: السبعه | F19: مدرسه | G19: Low | H19: Interested
A20: 45897 | B20: مدرسة شمس الوطن | C20: بسمة رجب علي بالخير | D20: 926770720 | E20: عين زاره السدرة | F20: مدرسه | G20: High | H20: Interested | I20: 800 طالب
A21: 45898 | B21: XGYM | C21: ناجي بن نو به | D21: 919322228 | E21: طريق الشط فتحت النادي البحري | F21: صالة رياضه | G21: Low | H21: Interested
A22: 45899 | B22: أكاديمية باز لعلوم الطيران | C22: ونيس فوزي الشلماني | D22: 926737125 | E22: السراج | F22: أكاديمية طيران دولية | G22: Low | H22: Interested
A23: 45899 | B23: اكادمية سيناء | C23: امين القماطي | D23: 925058379 | E23: سوق الجمعة / جزيرة اولاد دياب معيتيقة | F23: اكادمية | G23: Low | H23: New Lead
A24: 45900 | B24: شركة بريستو ايت | C24: احمد نجومه | D24: 914449901 | F24: شركه | G24: Medium | H24: Interested | I24: شركة توصيل تحتوي على 200 موظف في مبنى الادارة الرئيسية
A25: 45900 | B25: مركز المستقبل للدورات المنهجية | C25: ايناس | D25: 911135555 | F25: مركز كورسات | G25: Low | H25: Interested
A26: 45909 | B26: ثانوية افريقيا | C26: حواء ادم | D26: 913379230 | E26: السراج | F26: مدرسه | G26: High | H26: Interested | I26: مدرسه بها 600 طالب و 150 معلمه

Sheet Summary
A3: Category | B3: Total COGS | C3: Total Revenue | D3: Total Profit
A4: Drinks | B4: =sum(B12+B19) -> 11471.33 | C4: =sum(C12+C19) -> 19077 | D4: =sum(D12+D19) -> 7873.99
A5: Snacks | B5: =sum(B13+B20) -> 7066.064 | C5: =sum(C13+C20) -> 10667 | D5: =sum(D13+D20) -> 3600.936
A6: Chips | B6: =sum(B14+B21) -> 8419.47 | C6: =sum(C14+C21) -> 13351 | D6: =sum(D14+D21) -> 6639.04
A7: Total | B7: =SUM(B4:B6) -> 26956.864 | C7: =SUM(C4:C6) -> 43095 | D7: =SUM(D4:D6) -> 18113.966
A11: Column 1 | B11: Total COGS | C11: Total Revenue | D11: Total Profit | F11: Category | G11: Total COGS | H11: Total Revenue | I11: Total Profit | K11: Category | L11: Total COGS | M11: Total Revenue | N11: Total Profit | P11: Category | Q11: Total COGS | R11: Total Revenue | S11: Total Profit
A12: Drinks | B12: =(Drinks!N40) -> 7541.61 | C12: =(Drinks!O40) -> 12450 | D12: =(Drinks!P40) -> 4908.39 | F12: Drinks | G12: =(Drinks!N13) -> 2665.95 | H12: =(Drinks!O13) -> 4554 | I12: =(Drinks!P13) -> 1888.05 | K12: Drinks | L12: =(Drinks!N28) -> 3077.34 | M12: =(Drinks!O28) -> 5172 | N12: =(Drinks!P28) -> 2094.66 | P12: Drinks | Q12: =(Drinks!N38) -> 1798.32 | R12: =(Drinks!O38) -> 2724 | S12: =(Drinks!P38) -> 925.68
A13: Snacks | B13: =(Snacks!N41) -> 2809.964 | C13: =(Snacks!O41) -> 3946 | D13: =(Snacks!P41) -> 1136.036 | F13: Snacks | G13: =(Snacks!N15) -> 1206.68 | H13: =(Snacks!O15) -> 1700 | I13: =(Snacks!P15) -> 493.32 | K13: Snacks | L13: =(Snacks!N30) -> 853.284 | M13: =(Snacks!O30) -> 1214 | N13: =(Snacks!P30) -> 360.716 | P13: Snacks | Q13: =(Snacks!N39) -> 750 | R13: =(Snacks!O39) -> 1032 | S13: =(Snacks!P39) -> 282
A14: Chips | B14: =(Chips!N31) -> 1811.66 | C14: =(Chips!O31) -> 2663 | D14: =(Chips!P32) -> 2558.85 | F14: Chips | G14: =(Chips!N6) -> 1519.8 | H14: =(Chips!O6) -> 2118 | I14: =(Chips!P6) -> 598.2 | K14: Chips | L14: =(Chips!N17) -> 1513.69 | M14: =(Chips!O17) -> 2623 | N14: =(Chips!P17) -> 1109.31 | P14: Chips | Q14: =(Chips!N31) -> 1811.66 | R14: =(Chips!O31) -> 2663 | S14: =(Chips!P31) -> 851.34
A15: Total | B15: =SUM(B12:B14) -> 12163.234 | C15: =SUM(C12:C14) -> 19059 | D15: =SUM(D12:D14) -> 8603.276 | F15: Total | G15: =SUM(G12:G14) -> 5392.43 | H15: =SUM(H12:H14) -> 8372 | I15: =SUM(I12:I14) -> 2979.57 | K15: Total | L15: =SUM(L12:L14) -> 5444.314 | M15: =SUM(M12:M14) -> 9009 | N15: =SUM(N12:N14) -> 3564.686 | P15: Total | Q15: =SUM(Q12:Q14) -> 4359.98 | R15: =SUM(R12:R14) -> 6419 | S15: =SUM(S12:S14) -> 2059.02
A18: Column 1 | B18: Column 2 | C18: Column 3 | D18: Column 4 | F18: Category | G18: Total COGS | H18: Total Revenue | I18: Total Profit | K18: Category | L18: Total COGS | M18: Total Revenue | N18: Total Profit | P18: Category | Q18: Total COGS | R18: Total Revenue | S18: Total Profit | U18: Commodity type | V18: Pay by cash | W18: Quantity | X18: Profit | Y18: Gross margin | Z18: Proportion | AA18: Total amount | AB18: Total quantity | AD18: Commodity type | AE18: Pay by cash | AF18: Quantity | AG18: Profit | AH18: Gross margin | AI18: Proportion | AJ18: Total amount | AK18: Total quantity
A19: Drinks | B19: =(Drinks!N108) -> 3929.72 | C19: =(Drinks!O108) -> 6627 | D19: =(Drinks!P108) -> 2965.6 | F19: Drinks | G19: =(Drinks!N57) -> 1638.68 | H19: =(Drinks!O57) -> 2799 | I19: =(Drinks!P57) -> 1160.32 | K19: Drinks | L19: =(Drinks!N74) -> 1027.2 | M19: =(Drinks!O74) -> 1656 | N19: =(Drinks!P74) -> 897.12 | P19: Drinks | Q19: =(Drinks!N90) -> 1263.84 | R19: =(Drinks!O90) -> 2172 | S19: =(Drinks!P90) -> 908.16 | U19: Water | V19: 712 | W19: 712 | X19: 497.88 | Y19: 0.6993 | Z19: 0.0501 | AA19: 712 | AB19: 712 | AD19: Water | AE19: 416 | AF19: 412 | AG19: 296.52 | AH19: 0.7128 | AI19: 0.059 | AJ19: 416 | AK19: 412
A20: Snacks | B20: =(Snacks!N104) -> 4256.1 | C20: =(Snacks!O104) -> 6721 | D20: =(Snacks!P104) -> 2464.9 | F20: Snacks | G20: =(Snacks!N53) -> 742.68 | H20: =(Snacks!O53) -> 1133 | I20: =(Snacks!P53) -> 390.32 | K20: Snacks | L20: =(Snacks!N67) -> 1368.24 | M20: =(Snacks!O67) -> 2262 | N20: =(Snacks!P67) -> 893.76 | P20: Snacks | Q20: =(Snacks!N84) -> 2145.18 | R20: =(Snacks!O84) -> 3326 | S20: =(Snacks!P84) -> 1180.82 | U20: Drink | V20: 2972 | W20: 1242 | X20: 944.62 | Y20: 0.3178 | Z20: 0.2092 | AA20: 2972 | AB20: 1242 | AD20: Chocolates | AE20: 1646 | AF20: 687 | AG20: 638.78 | AH20: 0.3881 | AI20: 0.2336 | AJ20: 1646 | AK20: 687
A21: Chips | B21: =(Chips!N80) -> 6607.81 | C21: =(Chips!O80) -> 10688 | D21: =(Chips!P80) -> 4080.19 | F21: Chips | G21: =(Chips!N47) -> 1986.63 | H21: =(Chips!O47) -> 3429 | I21: =(Chips!P47) -> 1442.37 | K21: Chips | L21: =(Chips!N58) -> 2251.36 | M21: =(Chips!O58) -> 3446 | N21: =(Chips!P58) -> 1194.64 | P21: Chips | Q21: =(Chips!N69) -> 2369.82 | R21: =(Chips!O69) -> 3813 | S21: =(Chips!P69) -> 1443.18 | U21: Chocolates | V21: 3418 | W21: 1328 | X21: 1273.17 | Y21: 0.3725 | Z21: 0.2406 | AA21: 3418 | AB21: 1328 | AD21: Drink | AE21: 1969 | AF21: 726 | AG21: 619.41 | AH21: 0.3146 | AI21: 0.2794 | AJ21: 1969 | AK21: 726
A22: Total | B22: =SUM(B19:B21) -> 14793.63 | C22: =SUM(C19:C21) -> 24036 | D22: =SUM(D19:D21) -> 9510.69 | F22: Total | G22: =SUM(G19:G21) -> 4367.99 | H22: =SUM(H19:H21) -> 7361 | I22: =SUM(I19:I21) -> 2993.01 | K22: Total | L22: =SUM(L19:L21) -> 4646.8 | M22: =SUM(M19:M21) -> 7364 | N22: =SUM(N19:N21) -> 2985.52 | P22: Total | Q22: =SUM(Q19:Q21) -> 5778.84 | R22: =SUM(R19:R21) -> 9311 | S22: =SUM(S19:S21) -> 3532.16 | U22: Chips | V22: 7102 | W22: 1551 | X22: 3122.8 | Y22: 0.4397 | Z22: 0.5 | AA22: 7102 | AB22: 1551 | AD22: Chips | AE22: 3016 | AF22: 589 | AG22: 1337.06 | AH22: 0.4433 | AI22: 0.428 | AJ22: 3016 | AK22: 589
U23: Total | V23: 15847 | W23: 4833 | X23: 6513.117 | Y23: 0.411 | Z23: 1 | AA23: 14204 | AB23: 4833 | AD23: Total | AE23: 7047 | AF23: 2414 | AG23: 2891.77 | AH23: 0.4104 | AI23: 1 | AJ23: 7047 | AK23: 2414

Sheet REstock prod
A4: Date | B4: Description
A5: 45705 | B5: تم ادخال فاتوره
A6: 45708
A7: 45714
A8: 45716
A9: 45724
A10: 45728
A11: 45729
A12: 45732
A13: 45733
A14: 45735
A15: 45736
A16: 45738
A17: 45741
... A30: 45773

Sheet Drinks
A1: Product Name | B1: # pack | C1: items inside the pack | D1: Initial Stock | E1: Cost per Unit | F1: Selling Price per Unit | G1: margin profit | H1: # packs sold | I1: Quantity Sold | J1: # pack Restoked | K1: Restocked Quantity | L1: # Curremt packs | M1: Current Stock | N1: COGS | O1: Revenue | P1: Gross Profit | Q1: Month
A2: Water | B2: 133 | C2: 12 | D2: =(B2*C2) -> 1596 | E2: 0.3 | F2: 1 | G2: =((F2-E2)/F2)*100 & "%" -> 70% | H2: 133 | I2: =(C2*H2) -> 1596 | J2: 0 | K2: =(C2*J2) -> 0 | L2: =(B2+J2-H2) -> 0 | M2: =(D2+K2)-I2 -> 0 | N2: =(D2 + K2 - M2) * E2 -> 478.8 | O2: =(I2*F2) -> 1596 | P2: =(O2-N2) -> 1117.2 | Q2: 8
A3: Green | B3: 5 | C3: 24 | D3: 120 | E3: 2.58 | F3: 3 | G3: =((F3-E3)/F3)*100 & "%" -> 14.% | H3: 5 | I3: =(C3*H3) -> 120 | K3: =(C3*J3) -> 0 | M3: =(D3+K3)-I3 -> 0 | N3: =(D3 + K3 - M3) * E3 -> 309.6 | O3: =(I3*F3) -> 360 | P3: =(O3-N3) -> 50.4 | Q3: 8
A4: X!R | B4: 9 | C4: 24 | D4: 216 | E4: 2.91 | F4: 4 | G4: =((F4-E4)/F4)*100 & "%" -> 27.25% | H4: 9 | I4: =(C4*H4) -> 216 | J4: 0 | K4: =(C4*J4) -> 0 | L4: =(B4+J4-H4) -> 0 | M4: =(D4+K4)-I4 -> 0 | N4: =(D4 + K4 - M4) * E4 -> 628.56 | O4: =(I4*F4) -> 864 | P4: =(O4-N4) -> 235.44 | Q4: 8
A5: King | B5: 4 | C5: 24 | D5: =B5*C5 -> 96 | E5: 1.75 | F5: 2 | G5: =((F5-E5)/F5)*100 & "%" -> 12.5% | H5: 4 | I5: =(C5*H5) -> 96 | J5: 0 | K5: =(C5*J5) -> 0 | M5: =(D5+K5)-I5 -> 0 | N5: =(D5 + K5 - M5) * E5 -> 168 | O5: =(I5*F5) -> 192 | P5: =(O5-N5) -> 24 | Q5: 8
A6: Power | B6: 3 | C6: 24 | D6: =B6*C6 -> 72 | E6: 2.5 | F6: 3 | G6: =((F6-E6)/F6)*100 & "%" -> 16.6666666666667% | H6: 3 | I6: =(C6*H6) -> 72 | J6: 0 | K6: =(C6*J6) -> 0 | M6: =(D6+K6)-I6 -> 0 | N6: =(D6 + K6 - M6) * E6 -> 180 | O6: =(I6*F6) -> 216 | P6: =(O6-N6) -> 36 | Q6: 8
A7: Mogu Mogu | B7: 1 | C7: 24 | D7: =(B7*C7) -> 24 | E7: 8.54 | F7: 10 | G7: =((F7-E7)/F7)*100 & "%" -> 14.6% | H7: 1 | I7: =(C7*H7) -> 24 | K7: =(C7*J7) -> 0 | L7: 0 | M7: =(D7+K7)-I7 -> 0 | N7: =(D7 + K7 - M7) * E7 -> 204.96 | O7: =(I7*F7) -> 240 | P7: =(O7-N7) -> 35.04 | Q7: 8
A8: سن توب سعودي | B8: 30 | C8: 24 | D8: =(B8*C8) -> 720 | E8: 0.6 | F8: 1 | G8: =((F8-E8)/F8)*100 & "%" -> 40% | H8: 30 | I8: =(C8*H8) -> 720 | J8: 0 | K8: =(C8*J8) -> 0 | M8: =(D8+K8)-I8 -> 0 | N8: =(D8 + K8 - M8) * E8 -> 432 | O8: =(I8*F8) -> 720 | P8: =(O8-N8) -> 288 | Q8: 8
A9: الندى زنجبيل | D9: 18 | E9: 2.055 | F9: 3 | G9: =((F9-E9)/F9)*100 & "%" -> 31.5% | I9: 18 | K9: =(C9*J9) -> 0 | M9: =(D9+K9)-I9 -> 0 | N9: =(D9 + K9 - M9) * E9 -> 36.99 | O9: =(I9*F9) -> 54 | P9: =(O9-N9) -> 17.01 | Q9: 8
A10: بتري الندى | D10: 18 | E10: 1.56 | F10: 2 | G10: =((F10-E10)/F10)*100 & "%" -> 22.% | I10: 18 | K10: =(C10*J10) -> 0 | M10: =(D10+K10)-I10 -> 0 | N10: =(D10 + K10 - M10) * E10 -> 28.08 | O10: =(I10*F10) -> 36 | P10: =(O10-N10) -> 7.92 | Q10: 8
A11: الندى عنب | D11: 36 | E11: 2.61 | F11: 3 | G11: =((F11-E11)/F11)*100 & "%" -> 13.% | I11: 36 | K11: =(C11*J11) -> 0 | M11: =(D11+K11)-I11 -> 0 | N11: =(D11 + K11 - M11) * E11 -> 93.96 | O11: =(I11*F11) -> 108 | P11: =(O11-N11) -> 14.04 | Q11: 8
A12: العين طلقه | D12: 84 | E12: 1.25 | F12: 2 | G12: =((F12-E12)/F12)*100 & "%" -> 37.5% | I12: 84 | K12: =(C12*J12) -> 0 | M12: =(D12+K12)-I12 -> 0 | N12: =(D12 + K12 - M12) * E12 -> 105 | O12: =(I12*F12) -> 168 | P12: =(O12-N12) -> 63 | Q12: 8
