Workbook

Sheet KPI_Calc
F1: Ads Income | G1: Rent | H1: Net Profit | I1: Avg Price | J1: SPI_Traffic | K1: SPI_Profit | L1: SPI_Final | M1: Rank per month
G2: {=IFERROR(XLOOKUP(B2, Machines!A:A, Machines!C:C), 0)} -> 0 | H2: =IFERROR( D2 + F2 - G2, 0) -> 439.36 | I2: =IF(OR($B2="",RIGHT($A2,5)="Total"),"", $C2 / $E2) -> 4.2164751 | J2: =IFERROR(__xludf.DUMMYFUNCTION("IF($B2="""","""", 100 * $E2 / MAX(FILTER($E:$E, $A:$A=$A2, $B:$B<>"""")) ) "),100.0) -> 100 | K2: =IFERROR(__xludf.DUMMYFUNCTION("IF($B2="""","""", 100 * $H2 / MAX(FILTER($H:$H, $A:$A=$A2, $B:$B<>"""")) ) "),100.0) -> 100 | L2: =IF($B2="","", 0.4*$I2 + 0.6*$J2) -> 61.68659 | M2: =IFERROR(__xludf.DUMMYFUNCTION("IF($B2="""","""", RANK($K2, FILTER($K:$K, $A:$A=$A2, $B:$B<>""""), 0) ) "),1.0) -> 1 | N2: =IF($B2="","", IF($L2>=60,"🟢 Strong", IF($L2>=35,"🟡 Watch", "🔴 Action Needed"))) -> 🟢 Strong | O2: =IF($B2="","", IF($N2="🟢 Strong","OK", IF($K2<$J2,"Profit issue → pricing/cost/rent", "Traffic issue → location/product mix"))) -> OK
F3: 1000 | G3: 500 | H3: =IFERROR( D3 + F3 - G3, 0) -> 3949.24 | I3: =IF(OR($B3="",RIGHT($A3,5)="Total"),"", $C3 / $E3) -> 3.4337553 | J3: =IFERROR(__xludf.DUMMYFUNCTION("IF($B3="""","""", 100 * $E3 / MAX(FILTER($E:$E, $A:$A=$A3, $B:$B<>"""")) ) "),52.3756906077348) -> 52.375691 | K3: =IFERROR(__xludf.DUMMYFUNCTION("IF($B3="""","""", 100 * $H3 / MAX(FILTER($H:$H, $A:$A=$A3, $B:$B<>"""")) ) "),73.06155371705124) -> 73.061554 | L3: =IF($B3="","", 0.4*$I3 + 0.6*$J3) -> 32.798916 | M3: =IFERROR(__xludf.DUMMYFUNCTION("IF($B3="""","""", RANK($K3, FILTER($K:$K, $A:$A=$A3, $B:$B<>""""), 0) ) "),4.0) -> 4 | N3: =IF($B3="","", IF($L3>=60,"🟢 Strong", IF($L3>=35,"🟡 Watch", "🔴 Action Needed"))) -> 🔴 Action Needed | O3: =IF($B3="","", IF($N3="🟢 Strong","OK", IF($K3<$J3,"Profit issue → pricing/cost/rent", "Traffic issue → location/product mix"))) -> Traffic issue → location/product mix
H4: =IFERROR( D4 + F4 - G4, 0) -> 1626.18 | I4: =IF(OR($B4="",RIGHT($A4,5)="Total"),"", $C4 / $E4) -> 3.3972603 | J4: =IFERROR(__xludf.DUMMYFUNCTION("IF($B4="""","""", 100 * $E4 / MAX(FILTER($E:$E, $A:$A=$A4, $B:$B<>"""")) ) "),30.65193370165746) -> 30.651934 | K4: =IFERROR(__xludf.DUMMYFUNCTION("IF($B4="""","""", 100 * $H4 / MAX(FILTER($H:$H, $A:$A=$A4, $B:$B<>"""")) ) "),30.084582710494768) -> 30.084583 | L4: =IF($B4="","", 0.4*$I4 + 0.6*$J4) -> 19.750064 | M4: =IFERROR(__xludf.DUMMYFUNCTION("IF($B4="""","""", RANK($K4, FILTER($K:$K, $A:$A=$A4, $B:$B<>""""), 0) ) "),13.0) -> 13 | N4: =IF($B4="","", IF($L4>=60,"🟢 Strong", IF($L4>=35,"🟡 Watch", "🔴 Action Needed"))) -> 🔴 Action Needed | O4: =IF($B4="","", IF($N4="🟢 Strong","OK", IF($K4<$J4,"Profit issue → pricing/cost/rent", "Traffic issue → location/product mix"))) -> Profit issue → pricing/cost/rent
F5: 1000 | H5: =IFERROR( D5 + F5 - G5, 0) -> 3587.57 | I5: =IF(OR($B5="",RIGHT($A5,5)="Total"),"", $C5 / $E5) -> 3.2060277 | J5: =IFERROR(__xludf.DUMMYFUNCTION("IF($B5="""","""", 100 * $E5 / MAX(FILTER($E:$E, $A:$A=$A5, $B:$B<>"""")) ) "),44.729281767955804) -> 44.729282 | K5: =IFERROR(__xludf.DUMMYFUNCTION("IF($B5="""","""", 100 * $H5 / MAX(FILTER($H:$H, $A:$A=$A5, $B:$B<>"""")) ) "),66.37060251306113) -> 66.370603 | L5: =IF($B5="","", 0.4*$I5 + 0.6*$J5) -> 28.11998 | M5: =IFERROR(__xludf.DUMMYFUNCTION("IF($B5="""","""", RANK($K5, FILTER($K:$K, $A:$A=$A5, $B:$B<>""""), 0) ) "),5.0) -> 5 | N5: =IF($B5="","", IF($L5>=60,"🟢 Strong", IF($L5>=35,"🟡 Watch", "🔴 Action Needed"))) -> 🔴 Action Needed | O5: =IF($B5="","", IF($N5="🟢 Strong","OK", IF($K5<$J5,"Profit issue → pricing/cost/rent", "Traffic issue → location/product mix"))) -> Traffic issue → location/product mix
G6: {=IFERROR(XLOOKUP(B6, Machines!A:A, Machines!C:C), 0)} -> 1000 | H6: =IFERROR( D6 + F6 - G6, 0) -> 5405.36 | I6: =IF(OR($B6="",RIGHT($A6,5)="Total"),"", $C6 / $E6) -> 3.2948066 | J6: =IFERROR(__xludf.DUMMYFUNCTION("IF($B6="""","""", 100 * $E6 / MAX(FILTER($E:$E, $A:$A=$A6, $B:$B<>"""")) ) "),100.0) -> 100 | K6: =IFERROR(__xludf.DUMMYFUNCTION("IF($B6="""","""", 100 * $H6 / MAX(FILTER($H:$H, $A:$A=$A6, $B:$B<>"""")) ) "),100.0) -> 100 | L6: =IF($B6="","", 0.4*$I6 + 0.6*$J6) -> 61.317923 | M6: =IFERROR(__xludf.DUMMYFUNCTION("IF($B6="""","""", RANK($K6, FILTER($K:$K, $A:$A=$A6, $B:$B<>""""), 0) ) "),1.0) -> 1 | N6: =IF($B6="","", IF($L6>=60,"🟢 Strong", IF($L6>=35,"🟡 Watch", "🔴 Action Needed"))) -> 🟢 Strong | O6: =IF($B6="","", IF($N6="🟢 Strong","OK", IF($K6<$J6,"Profit issue → pricing/cost/rent", "Traffic issue → location/product mix"))) -> OK
H7: =IFERROR( D7 + F7 - G7, 0) -> 1445.9 | I7: =IF(OR($B7="",RIGHT($A7,5)="Total"),"", $C7 / $E7) -> 3.0787901 | J7: =IFERROR(__xludf.DUMMYFUNCTION("IF($B7="""","""", 100 * $E7 / MAX(FILTER($E:$E, $A:$A=$A7, $B:$B<>"""")) ) "),29.591160220994475) -> 29.59116 | K7: =IFERROR(__xludf.DUMMYFUNCTION("IF($B7="""","""", 100 * $H7 / MAX(FILTER($H:$H, $A:$A=$A7, $B:$B<>"""")) ) "),26.74937469474744) -> 26.749375 | L7: =IF($B7="","", 0.4*$I7 + 0.6*$J7) -> 18.986212 | M7: =IFERROR(__xludf.DUMMYFUNCTION("IF($B7="""","""", RANK($K7, FILTER($K:$K, $A:$A=$A7, $B:$B<>""""), 0) ) "),16.0) -> 16 | N7: =IF($B7="","", IF($L7>=60,"🟢 Strong", IF($L7>=35,"🟡 Watch", "🔴 Action Needed"))) -> 🔴 Action Needed | O7: =IF($B7="","", IF($N7="🟢 Strong","OK", IF($K7<$J7,"Profit issue → pricing/cost/rent", "Traffic issue → location/product mix"))) -> Profit issue → pricing/cost/rent
H8: =IFERROR( D8 + F9 - G8, 0) -> 447.8 | I8: =IF(OR($B8="",RIGHT($A8,5)="Total"),"", $C8 / $E8) -> 4.6079545 | J8: =IFERROR(__xludf.DUMMYFUNCTION("IF($B8="""","""", 100 * $E8 / MAX(FILTER($E:$E, $A:$A=$A8, $B:$B<>"""")) ) "),3.889502762430939) -> 3.8895028 | K8: =IFERROR(__xludf.DUMMYFUNCTION("IF($B8="""","""", 100 * $H8 / MAX(FILTER($H:$H, $A:$A=$A8, $B:$B<>"""")) ) "),8.284369588704548) -> 8.2843696 | L8: =IF($B8="","", 0.4*$I8 + 0.6*$J8) -> 4.1768835 | M8: =IFERROR(__xludf.DUMMYFUNCTION("IF($B8="""","""", RANK($K8, FILTER($K:$K, $A:$A=$A8, $B:$B<>""""), 0) ) "),24.0) -> 24 | N8: =IF($B8="","", IF($L8>=60,"🟢 Strong", IF($L8>=35,"🟡 Watch", "🔴 Action Needed"))) -> 🔴 Action Needed | O8: =IF($B8="","", IF($N8="🟢 Strong","OK", IF($K8<$J8,"Profit issue → pricing/cost/rent", "Traffic issue → location/product mix"))) -> Traffic issue → location/product mix
H9: =IFERROR( D9 + F9 - G9, 0) -> 16401.41 | I9: =IF(OR($B9="",RIGHT($A9,5)="Total"),"", $C9 / $E9) | J9: =IFERROR(__xludf.DUMMYFUNCTION("IF($B9="""","""", 100 * $E9 / MAX(FILTER($E:$E, $A:$A=$A9, $B:$B<>"""")) ) "),"") | K9: =IFERROR(__xludf.DUMMYFUNCTION("IF($B9="""","""", 100 * $H9 / MAX(FILTER($H:$H, $A:$A=$A9, $B:$B<>"""")) ) "),"") | L9: =IF($B9="","", 0.4*$I9 + 0.6*$J9) | M9: =IFERROR(__xludf.DUMMYFUNCTION("IF($B9="""","""", RANK($K9, FILTER($K:$K, $A:$A=$A9, $B:$B<>""""), 0) ) "),"") | N9: =IF($B9="","", IF($L9>=60,"🟢 Strong", IF($L9>=35,"🟡 Watch", "🔴 Action Needed"))) | O9: =IF($B9="","", IF($N9="🟢 Strong","OK", IF($K9<$J9,"Profit issue → pricing/cost/rent", "Traffic issue → location/product mix")))
G10: {=IFERROR(XLOOKUP(B10, Machines!A:A, Machines!C:C), 0)} -> 0 | H10: =IFERROR( D10 + F10 - G10, 0) -> 1306.17 | I10: =IF(OR($B10="",RIGHT($A10,5)="Total"),"", $C10 / $E10) -> 3.4069586 | J10: =IFERROR(__xludf.DUMMYFUNCTION("IF($B10="""","""", 100 * $E10 / MAX(FILTER($E:$E, $A:$A=$A10, $B:$B<>"""")) ) "),100.0) -> 100 | K10: =IFERROR(__xludf.DUMMYFUNCTION("IF($B10="""","""", 100 * $H10 / MAX(FILTER($H:$H, $A:$A=$A10, $B:$B<>"""")) ) "),100.0) -> 100 | L10: =IF($B10="","", 0.4*$I10 + 0.6*$J10) -> 61.362783 | M10: =IFERROR(__xludf.DUMMYFUNCTION("IF($B10="""","""", RANK($K10, FILTER($K:$K, $A:$A=$A10, $B:$B<>""""), 0) ) "),1.0) -> 1 | N10: =IF($B10="","", IF($L10>=60,"🟢 Strong", IF($L10>=35,"🟡 Watch", "🔴 Action Needed"))) -> 🟢 Strong | O10: =IF($B10="","", IF($N10="🟢 Strong","OK", IF($K10<$J10,"Profit issue → pricing/cost/rent", "Traffic issue → location/product mix"))) -> OK
F11: 1000 | G11: {=IFERROR(XLOOKUP(B11, Machines!A:A, Machines!C:C), 0)} -> 500 | H11: =IFERROR( D11 + F11 - G11, 0) -> 1515.1 | I11: =IF(OR($B11="",RIGHT($A11,5)="Total"),"", $C11 / $E11) -> 3.1438547 | J11: =IFERROR(__xludf.DUMMYFUNCTION("IF($B11="""","""", 100 * $E11 / MAX(FILTER($E:$E, $A:$A=$A11, $B:$B<>"""")) ) "),15.823204419889503) -> 15.823204 | K11: =IFERROR(__xludf.DUMMYFUNCTION("IF($B11="""","""", 100 * $H11 / MAX(FILTER($H:$H, $A:$A=$A11, $B:$B<>"""")) ) "),28.029585448517775) -> 28.029585 | L11: =IF($B11="","", 0.4*$I11 + 0.6*$J11) -> 10.751465 | M11: =IFERROR(__xludf.DUMMYFUNCTION("IF($B11="""","""", RANK($K11, FILTER($K:$K, $A:$A=$A11, $B:$B<>""""), 0) ) "),15.0) -> 15 | N11: =IF($B11="","", IF($L11>=60,"🟢 Strong", IF($L11>=35,"🟡 Watch", "🔴 Action Needed"))) -> 🔴 Action Needed | O11: =IF($B11="","", IF($N11="🟢 Strong","OK", IF($K11<$J11,"Profit issue → pricing/cost/rent", "Traffic issue → location/product mix"))) -> Traffic issue → location/product mix
H12: =IFERROR( D12 + F12 - G12, 0) -> 1368.57 | I12: =IF(OR($B12="",RIGHT($A12,5)="Total"),"", $C12 / $E12) -> 3.362916 | J12: =IFERROR(__xludf.DUMMYFUNCTION("IF($B12="""","""", 100 * $E12 / MAX(FILTER($E:$E, $A:$A=$A12, $B:$B<>"""")) ) "),27.88950276243094) -> 27.889503 | K12: =IFERROR(__xludf.DUMMYFUNCTION("IF($B12="""","""", 100 * $H12 / MAX(FILTER($H:$H, $A:$A=$A12, $B:$B<>"""")) ) "),25.318757677564502) -> 25.318758 | L12: =IF($B12="","", 0.4*$I12 + 0.6*$J12) -> 18.078868 | M12: =IFERROR(__xludf.DUMMYFUNCTION("IF($B12="""","""", RANK($K12, FILTER($K:$K, $A:$A=$A12, $B:$B<>""""), 0) ) "),17.0) -> 17 | N12: =IF($B12="","", IF($L12>=60,"🟢 Strong", IF($L12>=35,"🟡 Watch", "🔴 Action Needed"))) -> 🔴 Action Needed | O12: =IF($B12="","", IF($N12="🟢 Strong","OK", IF($K12<$J12,"Profit issue → pricing/cost/rent", "Traffic issue → location/product mix"))) -> Profit issue → pricing/cost/rent
H13: =IFERROR( D13 + F13 - G13, 0) -> 2969.46 | I13: =IF(OR($B13="",RIGHT($A13,5)="Total"),"", $C13 / $E13) -> 3.2778269 | J13: =IFERROR(__xludf.DUMMYFUNCTION("IF($B13="""","""", 100 * $E13 / MAX(FILTER($E:$E, $A:$A=$A13, $B:$B<>"""")) ) "),50.033149171270715) -> 50.033149 | K13: =IFERROR(__xludf.DUMMYFUNCTION("IF($B13="""","""", 100 * $H13 / MAX(FILTER($H:$H, $A:$A=$A13, $B:$B<>"""")) ) "),54.93547145796024) -> 54.935471 | L13: =IF($B13="","", 0.4*$I13 + 0.6*$J13) -> 31.33102 | M13: =IFERROR(__xludf.DUMMYFUNCTION("IF($B13="""","""", RANK($K13, FILTER($K:$K, $A:$A=$A13, $B:$B<>""""), 0) ) "),7.0) -> 7 | N13: =IF($B13="","", IF($L13>=60,"🟢 Strong", IF($L13>=35,"🟡 Watch", "🔴 Action Needed"))) -> 🔴 Action Needed | O13: =IF($B13="","", IF($N13="🟢 Strong","OK", IF($K13<$J13,"Profit issue → pricing/cost/rent", "Traffic issue → location/product mix"))) -> Traffic issue → location/product mix
F14: 1000 | G14: 1000 | H14: =IFERROR( D14 + F14 - G14, 0) -> 1639.68 | I14: =IF(OR($B14="",RIGHT($A14,5)="Total"),"", $C14 / $E14) -> 2.7793034 | J14: =IFERROR(__xludf.DUMMYFUNCTION("IF($B14="""","""", 100 * $E14 / MAX(FILTER($E:$E, $A:$A=$A14, $B:$B<>"""")) ) "),32.994475138121544) -> 32.994475 | K14: =IFERROR(__xludf.DUMMYFUNCTION("IF($B14="""","""", 100 * $H14 / MAX(FILTER($H:$H, $A:$A=$A14, $B:$B<>"""")) ) "),30.334334808412393) -> 30.334335 | L14: =IF($B14="","", 0.4*$I14 + 0.6*$J14) -> 20.908406 | M14: =IFERROR(__xludf.DUMMYFUNCTION("IF($B14="""","""", RANK($K14, FILTER($K:$K, $A:$A=$A14, $B:$B<>""""), 0) ) "),12.0) -> 12 | N14: =IF($B14="","", IF($L14>=60,"🟢 Strong", IF($L14>=35,"🟡 Watch", "🔴 Action Needed"))) -> 🔴 Action Needed | O14: =IF($B14="","", IF($N14="🟢 Strong","OK", IF($K14<$J14,"Profit issue → pricing/cost/rent", "Traffic issue → location/product mix"))) -> Profit issue → pricing/cost/rent
G15: {=IFERROR(XLOOKUP(B15, Machines!A:A, Machines!C:C), 0)} -> 0 | H15: =IFERROR( D15 + F15 - G15, 0) -> 1033.65 | I15: =IF(OR($B15="",RIGHT($A15,5)="Total"),"", $C15 / $E15) -> 3.1209752 | J15: =IFERROR(__xludf.DUMMYFUNCTION("IF($B15="""","""", 100 * $E15 / MAX(FILTER($E:$E, $A:$A=$A15, $B:$B<>"""")) ) "),24.022099447513813) -> 24.022099 | K15: =IFERROR(__xludf.DUMMYFUNCTION("IF($B15="""","""", 100 * $H15 / MAX(FILTER($H:$H, $A:$A=$A15, $B:$B<>"""")) ) "),19.1226856305593) -> 19.122686 | L15: =IF($B15="","", 0.4*$I15 + 0.6*$J15) -> 15.66165 | M15: =IFERROR(__xludf.DUMMYFUNCTION("IF($B15="""","""", RANK($K15, FILTER($K:$K, $A:$A=$A15, $B:$B<>""""), 0) ) "),20.0) -> 20 | N15: =IF($B15="","", IF($L15>=60,"🟢 Strong", IF($L15>=35,"🟡 Watch", "🔴 Action Needed"))) -> 🔴 Action Needed | O15: =IF($B15="","", IF($N15="🟢 Strong","OK", IF($K15<$J15,"Profit issue → pricing/cost/rent", "Traffic issue → location/product mix"))) -> Profit issue → pricing/cost/rent
G16: 300 | H16: =IFERROR( D16 + F18 - G16, 0) -> 4136.55 | I16: =IF(OR($B16="",RIGHT($A16,5)="Total"),"", $C16 / $E16) -> 4.1022831 | J16: =IFERROR(__xludf.DUMMYFUNCTION("IF($B16="""","""", 100 * $E16 / MAX(FILTER($E:$E, $A:$A=$A16, $B:$B<>"""")) ) "),24.19889502762431) -> 24.198895 | K16: =IFERROR(__xludf.DUMMYFUNCTION("IF($B16="""","""", 100 * $H16 / MAX(FILTER($H:$H, $A:$A=$A16, $B:$B<>"""")) ) "),76.52681782526975) -> 76.526818 | L16: =IF($B16="","", 0.4*$I16 + 0.6*$J16) -> 16.16025 | M16: =IFERROR(__xludf.DUMMYFUNCTION("IF($B16="""","""", RANK($K16, FILTER($K:$K, $A:$A=$A16, $B:$B<>""""), 0) ) "),2.0) -> 2 | N16: =IF($B16="","", IF($L16>=60,"🟢 Strong", IF($L16>=35,"🟡 Watch", "🔴 Action Needed"))) -> 🔴 Action Needed | O16: =IF($B16="","", IF($N16="🟢 Strong","OK", IF($K16<$J16,"Profit issue → pricing/cost/rent", "Traffic issue → location/product mix"))) -> Traffic issue → location/product mix
H17: =IFERROR( D17 + F17 - G17, 0) -> 572.33 | I17: =IF(OR($B17="",RIGHT($A17,5)="Total"),"", $C17 / $E17) -> 4.4933921 | J17: =IFERROR(__xludf.DUMMYFUNCTION("IF($B17="""","""", 100 * $E17 / MAX(FILTER($E:$E, $A:$A=$A17, $B:$B<>"""")) ) "),5.016574585635359) -> 5.0165746 | K17: =IFERROR(__xludf.DUMMYFUNCTION("IF($B17="""","""", 100 * $H17 / MAX(FILTER($H:$H, $A:$A=$A17, $B:$B<>"""")) ) "),10.588193940829107) -> 10.588194 | L17: =IF($B17="","", 0.4*$I17 + 0.6*$J17) -> 4.8073016 | M17: =IFERROR(__xludf.DUMMYFUNCTION("IF($B17="""","""", RANK($K17, FILTER($K:$K, $A:$A=$A17, $B:$B<>""""), 0) ) "),22.0) -> 22 | N17: =IF($B17="","", IF($L17>=60,"🟢 Strong", IF($L17>=35,"🟡 Watch", "🔴 Action Needed"))) -> 🔴 Action Needed | O17: =IF($B17="","", IF($N17="🟢 Strong","OK", IF($K17<$J17,"Profit issue → pricing/cost/rent", "Traffic issue → location/product mix"))) -> Traffic issue → location/product mix
F18: =SUM(F10:F16) -> 2000 | H18: =IFERROR( D18 + F18 - G18, 0) -> 14341.51 | I18: =IF(OR($B18="",RIGHT($A18,5)="Total"),"", $C18 / $E18) | J18: =IFERROR(__xludf.DUMMYFUNCTION("IF($B18="""","""", 100 * $E18 / MAX(FILTER($E:$E, $A:$A=$A18, $B:$B<>"""")) ) "),"") | K18: =IFERROR(__xludf.DUMMYFUNCTION("IF($B18="""","""", 100 * $H18 / MAX(FILTER($H:$H, $A:$A=$A18, $B:$B<>"""")) ) "),"") | L18: =IF($B18="","", 0.4*$I18 + 0.6*$J18) | M18: =IFERROR(__xludf.DUMMYFUNCTION("IF($B18="""","""", RANK($K18, FILTER($K:$K, $A:$A=$A18, $B:$B<>""""), 0) ) "),"") | N18: =IF($B18="","", IF($L18>=60,"🟢 Strong", IF($L18>=35,"🟡 Watch", "🔴 Action Needed"))) | O18: =IF($B18="","", IF($N18="🟢 Strong","OK", IF($K18<$J18,"Profit issue → pricing/cost/rent", "Traffic issue → location/product mix")))
F19: 1000 | G19: 500 | H19: =IFERROR( D19 + F19 - G19, 0) -> 1677.36 | I19: =IF(OR($B19="",RIGHT($A19,5)="Total"),"", $C19 / $E19) -> 2.749004 | J19: =IFERROR(__xludf.DUMMYFUNCTION("IF($B19="""","""", 100 * $E19 / MAX(FILTER($E:$E, $A:$A=$A19, $B:$B<>"""")) ) "),100.0) -> 100 | K19: =IFERROR(__xludf.DUMMYFUNCTION("IF($B19="""","""", 100 * $H19 / MAX(FILTER($H:$H, $A:$A=$A19, $B:$B<>"""")) ) "),99.99999999999999) -> 100 | L19: =IF($B19="","", 0.4*$I19 + 0.6*$J19) -> 61.099602 | M19: =IFERROR(__xludf.DUMMYFUNCTION("IF($B19="""","""", RANK($K19, FILTER($K:$K, $A:$A=$A19, $B:$B<>""""), 0) ) "),1.0) -> 1 | N19: =IF($B19="","", IF($L19>=60,"🟢 Strong", IF($L19>=35,"🟡 Watch", "🔴 Action Needed"))) -> 🟢 Strong | O19: =IF($B19="","", IF($N19="🟢 Strong","OK", IF($K19<$J19,"Profit issue → pricing/cost/rent", "Traffic issue → location/product mix"))) -> OK
G20: {=IFERROR(XLOOKUP(B20, Machines!A:A, Machines!C:C), 0)} -> 0 | H20: =IFERROR( D20 + F20 - G20, 0) -> 1567.26 | I20: =IF(OR($B20="",RIGHT($A20,5)="Total"),"", $C20 / $E20) -> 3.153506 | J20: =IFERROR(__xludf.DUMMYFUNCTION("IF($B20="""","""", 100 * $E20 / MAX(FILTER($E:$E, $A:$A=$A20, $B:$B<>"""")) ) "),34.98342541436464) -> 34.983425 | K20: =IFERROR(__xludf.DUMMYFUNCTION("IF($B20="""","""", 100 * $H20 / MAX(FILTER($H:$H, $A:$A=$A20, $B:$B<>"""")) ) "),28.994553554249862) -> 28.994554 | L20: =IF($B20="","", 0.4*$I20 + 0.6*$J20) -> 22.251458 | M20: =IFERROR(__xludf.DUMMYFUNCTION("IF($B20="""","""", RANK($K20, FILTER($K:$K, $A:$A=$A20, $B:$B<>""""), 0) ) "),14.0) -> 14 | N20: =IF($B20="","", IF($L20>=60,"🟢 Strong", IF($L20>=35,"🟡 Watch", "🔴 Action Needed"))) -> 🔴 Action Needed | O20: =IF($B20="","", IF($N20="🟢 Strong","OK", IF($K20<$J20,"Profit issue → pricing/cost/rent", "Traffic issue → location/product mix"))) -> Profit issue → pricing/cost/rent
F21: 1000 | G21: {=IFERROR(XLOOKUP(B21, Machines!A:A, Machines!C:C), 0)} -> 1000 | H21: =IFERROR( D21 + F21 - G21, 0) -> 4118.83 | I21: =IF(OR($B21="",RIGHT($A21,5)="Total"),"", $C21 / $E21) -> 2.9687951 | J21: =IFERROR(__xludf.DUMMYFUNCTION("IF($B21="""","""", 100 * $E21 / MAX(FILTER($E:$E, $A:$A=$A21, $B:$B<>"""")) ) "),76.48618784530387) -> 76.486188 | K21: =IFERROR(__xludf.DUMMYFUNCTION("IF($B21="""","""", 100 * $H21 / MAX(FILTER($H:$H, $A:$A=$A21, $B:$B<>"""")) ) "),76.1989950715586) -> 76.198995 | L21: =IF($B21="","", 0.4*$I21 + 0.6*$J21) -> 47.079231 | M21: =IFERROR(__xludf.DUMMYFUNCTION("IF($B21="""","""", RANK($K21, FILTER($K:$K, $A:$A=$A21, $B:$B<>""""), 0) ) "),3.0) -> 3 | N21: =IF($B21="","", IF($L21>=60,"🟢 Strong", IF($L21>=35,"🟡 Watch", "🔴 Action Needed"))) -> 🟡 Watch | O21: =IF($B21="","", IF($N21="🟢 Strong","OK", IF($K21<$J21,"Profit issue → pricing/cost/rent", "Traffic issue → location/product mix"))) -> Profit issue → pricing/cost/rent
H22: =IFERROR( D22 + F22 - G22, 0) -> 1014.02 | I22: =IF(OR($B22="",RIGHT($A22,5)="Total"),"", $C22 / $E22) -> 3.2355876 | J22: =IFERROR(__xludf.DUMMYFUNCTION("IF($B22="""","""", 100 * $E22 / MAX(FILTER($E:$E, $A:$A=$A22, $B:$B<>"""")) ) "),19.933701657458563) -> 19.933702 | K22: =IFERROR(__xludf.DUMMYFUNCTION("IF($B22="""","""", 100 * $H22 / MAX(FILTER($H:$H, $A:$A=$A22, $B:$B<>"""")) ) "),18.759527580031676) -> 18.759528 | L22: =IF($B22="","", 0.4*$I22 + 0.6*$J22) -> 13.254456 | M22: =IFERROR(__xludf.DUMMYFUNCTION("IF($B22="""","""", RANK($K22, FILTER($K:$K, $A:$A=$A22, $B:$B<>""""), 0) ) "),21.0) -> 21 | N22: =IF($B22="","", IF($L22>=60,"🟢 Strong", IF($L22>=35,"🟡 Watch", "🔴 Action Needed"))) -> 🔴 Action Needed | O22: =IF($B22="","", IF($N22="🟢 Strong","OK", IF($K22<$J22,"Profit issue → pricing/cost/rent", "Traffic issue → location/product mix"))) -> Profit issue → pricing/cost/rent
G23: 200 | H23: =IFERROR( D23 + F23 - G23, 0) -> 2245.81 | I23: =IF(OR($B23="",RIGHT($A23,5)="Total"),"", $C23 / $E23) -> 3.4748521 | J23: =IFERROR(__xludf.DUMMYFUNCTION("IF($B23="""","""", 100 * $E23 / MAX(FILTER($E:$E, $A:$A=$A23, $B:$B<>"""")) ) "),29.87845303867403) -> 29.878453 | K23: =IFERROR(__xludf.DUMMYFUNCTION("IF($B23="""","""", 100 * $H23 / MAX(FILTER($H:$H, $A:$A=$A23, $B:$B<>"""")) ) "),41.547834001805626) -> 41.547834 | L23: =IF($B23="","", 0.4*$I23 + 0.6*$J23) -> 19.317013 | M23: =IFERROR(__xludf.DUMMYFUNCTION("IF($B23="""","""", RANK($K23, FILTER($K:$K, $A:$A=$A23, $B:$B<>""""), 0) ) "),8.0) -> 8 | N23: =IF($B23="","", IF($L23>=60,"🟢 Strong", IF($L23>=35,"🟡 Watch", "🔴 Action Needed"))) -> 🔴 Action Needed | O23: =IF($B23="","", IF($N23="🟢 Strong","OK", IF($K23<$J23,"Profit issue → pricing/cost/rent", "Traffic issue → location/product mix"))) -> Traffic issue → location/product mix
F24: =SUM(F19:F23) -> 2000 | H24: =IFERROR( D24 + F24 - G24, 0) -> 12323.28 | I24: =IF(OR($B24="",RIGHT($A24,5)="Total"),"", $C24 / $E24) | J24: =IFERROR(__xludf.DUMMYFUNCTION("IF($B24="""","""", 100 * $E24 / MAX(FILTER($E:$E, $A:$A=$A24, $B:$B<>"""")) ) "),"") | K24: =IFERROR(__xludf.DUMMYFUNCTION("IF($B24="""","""", 100 * $H24 / MAX(FILTER($H:$H, $A:$A=$A24, $B:$B<>"""")) ) "),"") | L24: =IF($B24="","", 0.4*$I24 + 0.6*$J24) | M24: =IFERROR(__xludf.DUMMYFUNCTION("IF($B24="""","""", RANK($K24, FILTER($K:$K, $A:$A=$A24, $B:$B<>""""), 0) ) "),"") | N24: =IF($B24="","", IF($L24>=60,"🟢 Strong", IF($L24>=35,"🟡 Watch", "🔴 Action Needed"))) | O24: =IF($B24="","", IF($N24="🟢 Strong","OK", IF($K24<$J24,"Profit issue → pricing/cost/rent", "Traffic issue → location/product mix")))
F25: 1000 | H25: =IFERROR( D25 + F25 - G25, 0) -> 5270 | I25: =IF(OR($B25="",RIGHT($A25,5)="Total"),"", $C25 / $E25) -> 2.5584182 | J25: =IFERROR(__xludf.DUMMYFUNCTION("IF($B25="""","""", 100 * $E25 / MAX(FILTER($E:$E, $A:$A=$A25, $B:$B<>"""")) ) "),100.0) -> 100 | K25: =IFERROR(__xludf.DUMMYFUNCTION("IF($B25="""","""", 100 * $H25 / MAX(FILTER($H:$H, $A:$A=$A25, $B:$B<>"""")) ) "),100.0) -> 100 | L25: =IF($B25="","", 0.4*$I25 + 0.6*$J25) -> 61.023367 | M25: =IFERROR(__xludf.DUMMYFUNCTION("IF($B25="""","""", RANK($K25, FILTER($K:$K, $A:$A=$A25, $B:$B<>""""), 0) ) "),1.0) -> 1 | N25: =IF($B25="","", IF($L25>=60,"🟢 Strong", IF($L25>=35,"🟡 Watch", "🔴 Action Needed"))) -> 🟢 Strong | O25: =IF($B25="","", IF($N25="🟢 Strong","OK", IF($K25<$J25,"Profit issue → pricing/cost/rent", "Traffic issue → location/product mix"))) -> OK
H26: =IFERROR( D26 + F26 - G26, 0) -> 1786.24 | I26: =IF(OR($B26="",RIGHT($A26,5)="Total"),"", $C26 / $E26) -> 2.9173184 | J26: =IFERROR(__xludf.DUMMYFUNCTION("IF($B26="""","""", 100 * $E26 / MAX(FILTER($E:$E, $A:$A=$A26, $B:$B<>"""")) ) "),39.55801104972376) -> 39.558011 | K26: =IFERROR(__xludf.DUMMYFUNCTION("IF($B26="""","""", 100 * $H26 / MAX(FILTER($H:$H, $A:$A=$A26, $B:$B<>"""")) ) "),33.04571758402771) -> 33.045718 | L26: =IF($B26="","", 0.4*$I26 + 0.6*$J26) -> 24.901734 | M26: =IFERROR(__xludf.DUMMYFUNCTION("IF($B26="""","""", RANK($K26, FILTER($K:$K, $A:$A=$A26, $B:$B<>""""), 0) ) "),9.0) -> 9 | N26: =IF($B26="","", IF($L26>=60,"🟢 Strong", IF($L26>=35,"🟡 Watch", "🔴 Action Needed"))) -> 🔴 Action Needed | O26: =IF($B26="","", IF($N26="🟢 Strong","OK", IF($K26<$J26,"Profit issue → pricing/cost/rent", "Traffic issue → location/product mix"))) -> Profit issue → pricing/cost/rent
I27: =IF(OR($B27="",RIGHT($A27,5)="Total"),"", $C27 / $E27) -> 2.7702795 | J27: =IFERROR(__xludf.DUMMYFUNCTION("IF($B27="""","""", 100 * $E27 / MAX(FILTER($E:$E, $A:$A=$A27, $B:$B<>"""")) ) "),64.83977900552486) -> 64.839779 | K27: =IFERROR(__xludf.DUMMYFUNCTION("IF($B27="""","""", 100 * $H27 / MAX(FILTER($H:$H, $A:$A=$A27, $B:$B<>"""")) ) "),0.0) -> 0 | L27: =IF($B27="","", 0.4*$I27 + 0.6*$J27) -> 40.011979 | M27: =IFERROR(__xludf.DUMMYFUNCTION("IF($B27="""","""", RANK($K27, FILTER($K:$K, $A:$A=$A27, $B:$B<>""""), 0) ) "),25.0) -> 25 | N27: =IF($B27="","", IF($L27>=60,"🟢 Strong", IF($L27>=35,"🟡 Watch", "🔴 Action Needed"))) -> 🟡 Watch | O27: =IF($B27="","", IF($N27="🟢 Strong","OK", IF($K27<$J27,"Profit issue → pricing/cost/rent", "Traffic issue → location/product mix"))) -> Profit issue → pricing/cost/rent
F28: 1000 | G28: 1000 | H28: =IFERROR( D28 + F28 - G28, 0) -> 1752.25 | I28: =IF(OR($B28="",RIGHT($A28,5)="Total"),"", $C28 / $E28) -> 3.3529412 | J28: =IFERROR(__xludf.DUMMYFUNCTION("IF($B28="""","""", 100 * $E28 / MAX(FILTER($E:$E, $A:$A=$A28, $B:$B<>"""")) ) "),23.668508287292816) -> 23.668508 | K28: =IFERROR(__xludf.DUMMYFUNCTION("IF($B28="""","""", 100 * $H28 / MAX(FILTER($H:$H, $A:$A=$A28, $B:$B<>"""")) ) "),32.41689730193735) -> 32.416897 | L28: =IF($B28="","", 0.4*$I28 + 0.6*$J28) -> 15.542281 | M28: =IFERROR(__xludf.DUMMYFUNCTION("IF($B28="""","""", RANK($K28, FILTER($K:$K, $A:$A=$A28, $B:$B<>""""), 0) ) "),10.0) -> 10 | N28: =IF($B28="","", IF($L28>=60,"🟢 Strong", IF($L28>=35,"🟡 Watch", "🔴 Action Needed"))) -> 🔴 Action Needed | O28: =IF($B28="","", IF($N28="🟢 Strong","OK", IF($K28<$J28,"Profit issue → pricing/cost/rent", "Traffic issue → location/product mix"))) -> Traffic issue → location/product mix
F29: =SUM(F25:F28) -> 2000 | G29: 1000 | H29: =IFERROR( D29 + F29 - G29, 0) -> 12033.01 | I29: =IF(OR($B29="",RIGHT($A29,5)="Total"),"", $C29 / $E29) | J29: =IFERROR(__xludf.DUMMYFUNCTION("IF($B29="""","""", 100 * $E29 / MAX(FILTER($E:$E, $A:$A=$A29, $B:$B<>"""")) ) "),"") | K29: =IFERROR(__xludf.DUMMYFUNCTION("IF($B29="""","""", 100 * $H29 / MAX(FILTER($H:$H, $A:$A=$A29, $B:$B<>"""")) ) "),"") | L29: =IF($B29="","", 0.4*$I29 + 0.6*$J29) | M29: =IFERROR(__xludf.DUMMYFUNCTION("IF($B29="""","""", RANK($K29, FILTER($K:$K, $A:$A=$A29, $B:$B<>""""), 0) ) "),"") | N29: =IF($B29="","", IF($L29>=60,"🟢 Strong", IF($L29>=35,"🟡 Watch", "🔴 Action Needed"))) | O29: =IF($B29="","", IF($N29="🟢 Strong","OK", IF($K29<$J29,"Profit issue → pricing/cost/rent", "Traffic issue → location/product mix")))
F30: 1000 | H30: =IFERROR( D30 + F29 - G30, 0) -> 5760 | I30: =IF(OR($B30="",RIGHT($A30,5)="Total"),"", $C30 / $E30) -> 2.7187274 | J30: =IFERROR(__xludf.DUMMYFUNCTION("IF($B30="""","""", 100 * $E30 / MAX(FILTER($E:$E, $A:$A=$A30, $B:$B<>"""")) ) "),100.0) -> 100 | K30: =IFERROR(__xludf.DUMMYFUNCTION("IF($B30="""","""", 100 * $H30 / MAX(FILTER($H:$H, $A:$A=$A30, $B:$B<>"""")) ) "),100.0) -> 100 | L30: =IF($B30="","", 0.4*$I30 + 0.6*$J30) -> 61.087491 | M30: =IFERROR(__xludf.DUMMYFUNCTION("IF($B30="""","""", RANK($K30, FILTER($K:$K, $A:$A=$A30, $B:$B<>""""), 0) ) "),1.0) -> 1 | N30: =IF($B30="","", IF($L30>=60,"🟢 Strong", IF($L30>=35,"🟡 Watch", "🔴 Action Needed"))) -> 🟢 Strong | O30: =IF($B30="","", IF($N30="🟢 Strong","OK", IF($K30<$J30,"Profit issue → pricing/cost/rent", "Traffic issue → location/product mix"))) -> OK
H31: =IFERROR( D31 + F31 - G31, 0) -> 1140.2 | I31: =IF(OR($B31="",RIGHT($A31,5)="Total"),"", $C31 / $E31) -> 2.8326558 | J31: =IFERROR(__xludf.DUMMYFUNCTION("IF($B31="""","""", 100 * $E31 / MAX(FILTER($E:$E, $A:$A=$A31, $B:$B<>"""")) ) "),32.61878453038674) -> 32.618785 | K31: =IFERROR(__xludf.DUMMYFUNCTION("IF($B31="""","""", 100 * $H31 / MAX(FILTER($H:$H, $A:$A=$A31, $B:$B<>"""")) ) "),21.093877188568385) -> 21.093877 | L31: =IF($B31="","", 0.4*$I31 + 0.6*$J31) -> 20.704333 | M31: =IFERROR(__xludf.DUMMYFUNCTION("IF($B31="""","""", RANK($K31, FILTER($K:$K, $A:$A=$A31, $B:$B<>""""), 0) ) "),18.0) -> 18 | N31: =IF($B31="","", IF($L31>=60,"🟢 Strong", IF($L31>=35,"🟡 Watch", "🔴 Action Needed"))) -> 🔴 Action Needed | O31: =IF($B31="","", IF($N31="🟢 Strong","OK", IF($K31<$J31,"Profit issue → pricing/cost/rent", "Traffic issue → location/product mix"))) -> Profit issue → pricing/cost/rent
F32: 1000 | G32: 350 | I32: =IF(OR($B32="",RIGHT($A32,5)="Total"),"", $C32 / $E32) -> 2.6260959 | J32: =IFERROR(__xludf.DUMMYFUNCTION("IF($B32="""","""", 100 * $E32 / MAX(FILTER($E:$E, $A:$A=$A32, $B:$B<>"""")) ) "),42.850828729281766) -> 42.850829 | K32: =IFERROR(__xludf.DUMMYFUNCTION("IF($B32="""","""", 100 * $H32 / MAX(FILTER($H:$H, $A:$A=$A32, $B:$B<>"""")) ) "),0.0) -> 0 | L32: =IF($B32="","", 0.4*$I32 + 0.6*$J32) -> 26.760936 | M32: =IFERROR(__xludf.DUMMYFUNCTION("IF($B32="""","""", RANK($K32, FILTER($K:$K, $A:$A=$A32, $B:$B<>""""), 0) ) "),25.0) -> 25 | N32: =IF($B32="","", IF($L32>=60,"🟢 Strong", IF($L32>=35,"🟡 Watch", "🔴 Action Needed"))) -> 🔴 Action Needed | O32: =IF($B32="","", IF($N32="🟢 Strong","OK", IF($K32<$J32,"Profit issue → pricing/cost/rent", "Traffic issue → location/product mix"))) -> Profit issue → pricing/cost/rent
G33: 1000 | H33: =IFERROR( D33 + F33 - G33, 0) -> 570.52 | I33: =IF(OR($B33="",RIGHT($A33,5)="Total"),"", $C33 / $E33) -> 2.4701107 | J33: =IFERROR(__xludf.DUMMYFUNCTION("IF($B33="""","""", 100 * $E33 / MAX(FILTER($E:$E, $A:$A=$A33, $B:$B<>"""")) ) "),29.944751381215468) -> 29.944751 | K33: =IFERROR(__xludf.DUMMYFUNCTION("IF($B33="""","""", 100 * $H33 / MAX(FILTER($H:$H, $A:$A=$A33, $B:$B<>"""")) ) "),10.55470865955275) -> 10.554709 | L33: =IF($B33="","", 0.4*$I33 + 0.6*$J33) -> 18.954895 | M33: =IFERROR(__xludf.DUMMYFUNCTION("IF($B33="""","""", RANK($K33, FILTER($K:$K, $A:$A=$A33, $B:$B<>""""), 0) ) "),23.0) -> 23 | N33: =IF($B33="","", IF($L33>=60,"🟢 Strong", IF($L33>=35,"🟡 Watch", "🔴 Action Needed"))) -> 🔴 Action Needed | O33: =IF($B33="","", IF($N33="🟢 Strong","OK", IF($K33<$J33,"Profit issue → pricing/cost/rent", "Traffic issue → location/product mix"))) -> Profit issue → pricing/cost/rent
F34: =SUM(F30:F33) -> 2000 | G34: 0 | H34: =IFERROR( D34 + F34 - G34, 0) -> 10217.22 | I34: =IF(OR($B34="",RIGHT($A34,5)="Total"),"", $C34 / $E34) | J34: =IFERROR(__xludf.DUMMYFUNCTION("IF($B34="""","""", 100 * $E34 / MAX(FILTER($E:$E, $A:$A=$A34, $B:$B<>"""")) ) "),"") | K34: =IFERROR(__xludf.DUMMYFUNCTION("IF($B34="""","""", 100 * $H34 / MAX(FILTER($H:$H, $A:$A=$A34, $B:$B<>"""")) ) "),"") | L34: =IF($B34="","", 0.4*$I34 + 0.6*$J34) | M34: =IFERROR(__xludf.DUMMYFUNCTION("IF($B34="""","""", RANK($K34, FILTER($K:$K, $A:$A=$A34, $B:$B<>""""), 0) ) "),"") | N34: =IF($B34="","", IF($L34>=60,"🟢 Strong", IF($L34>=35,"🟡 Watch", "🔴 Action Needed"))) | O34: =IF($B34="","", IF($N34="🟢 Strong","OK", IF($K34<$J34,"Profit issue → pricing/cost/rent", "Traffic issue → location/product mix")))
H35: =IFERROR( D35 + F35 - G35, 0) -> 4317 | I35: =IF(OR($B35="",RIGHT($A35,5)="Total"),"", $C35 / $E35) -> 2.8934316 | J35: =IFERROR(__xludf.DUMMYFUNCTION("IF($B35="""","""", 100 * $E35 / MAX(FILTER($E:$E, $A:$A=$A35, $B:$B<>"""")) ) "),100.0) -> 100 | K35: =IFERROR(__xludf.DUMMYFUNCTION("IF($B35="""","""", 100 * $H35 / MAX(FILTER($H:$H, $A:$A=$A35, $B:$B<>"""")) ) "),100.0) -> 100 | L35: =IF($B35="","", 0.4*$I35 + 0.6*$J35) -> 61.157373 | M35: =IFERROR(__xludf.DUMMYFUNCTION("IF($B35="""","""", RANK($K35, FILTER($K:$K, $A:$A=$A35, $B:$B<>""""), 0) ) "),1.0) -> 1 | N35: =IF($B35="","", IF($L35>=60,"🟢 Strong", IF($L35>=35,"🟡 Watch", "🔴 Action Needed"))) -> 🟢 Strong | O35: =IF($B35="","", IF($N35="🟢 Strong","OK", IF($K35<$J35,"Profit issue → pricing/cost/rent", "Traffic issue → location/product mix"))) -> OK
G36: 350 | H36: =IFERROR( D36 + F36 - G36, 0) -> 1057.54 | I36: =IF(OR($B36="",RIGHT($A36,5)="Total"),"", $C36 / $E36) -> 3.1443489 | J36: =IFERROR(__xludf.DUMMYFUNCTION("IF($B36="""","""", 100 * $E36 / MAX(FILTER($E:$E, $A:$A=$A36, $B:$B<>"""")) ) "),35.97790055248619) -> 35.977901 | K36: =IFERROR(__xludf.DUMMYFUNCTION("IF($B36="""","""", 100 * $H36 / MAX(FILTER($H:$H, $A:$A=$A36, $B:$B<>"""")) ) "),19.56465434309649) -> 19.564654 | L36: =IF($B36="","", 0.4*$I36 + 0.6*$J36) -> 22.84448 | M36: =IFERROR(__xludf.DUMMYFUNCTION("IF($B36="""","""", RANK($K36, FILTER($K:$K, $A:$A=$A36, $B:$B<>""""), 0) ) "),19.0) -> 19 | N36: =IF($B36="","", IF($L36>=60,"🟢 Strong", IF($L36>=35,"🟡 Watch", "🔴 Action Needed"))) -> 🔴 Action Needed | O36: =IF($B36="","", IF($N36="🟢 Strong","OK", IF($K36<$J36,"Profit issue → pricing/cost/rent", "Traffic issue → location/product mix"))) -> Profit issue → pricing/cost/rent
F38: 1000 | G38: 1000 | H38: =IFERROR( D38 + F38 - G38, 0) -> 1704.18 | I38: =IF(OR($B38="",RIGHT($A38,5)="Total"),"", $C38 / $E38) -> 2.6682792 | J38: =IFERROR(__xludf.DUMMYFUNCTION("IF($B38="""","""", 100 * $E38 / MAX(FILTER($E:$E, $A:$A=$A38, $B:$B<>"""")) ) "),31.977900552486187) -> 31.977901 | K38: =IFERROR(__xludf.DUMMYFUNCTION("IF($B38="""","""", 100 * $H38 / MAX(FILTER($H:$H, $A:$A=$A38, $B:$B<>"""")) ) "),31.5275948317966) -> 31.527595 | L38: =IF($B38="","", 0.4*$I38 + 0.6*$J38) -> 20.254052 | M38: =IFERROR(__xludf.DUMMYFUNCTION("IF($B38="""","""", RANK($K38, FILTER($K:$K, $A:$A=$A38, $B:$B<>""""), 0) ) "),11.0) -> 11 | N38: =IF($B38="","", IF($L38>=60,"🟢 Strong", IF($L38>=35,"🟡 Watch", "🔴 Action Needed"))) -> 🔴 Action Needed | O38: =IF($B38="","", IF($N38="🟢 Strong","OK", IF($K38<$J38,"Profit issue → pricing/cost/rent", "Traffic issue → location/product mix"))) -> Profit issue → pricing/cost/rent
F39: 1000 | G39: 0 | H39: =IFERROR( D39 + F39 - G39, 0) -> 11001.51 | I39: =IF(OR($B39="",RIGHT($A39,5)="Total"),"", $C39 / $E39) | J39: =IFERROR(__xludf.DUMMYFUNCTION("IF($B39="""","""", 100 * $E39 / MAX(FILTER($E:$E, $A:$A=$A39, $B:$B<>"""")) ) "),"") | K39: =IFERROR(__xludf.DUMMYFUNCTION("IF($B39="""","""", 100 * $H39 / MAX(FILTER($H:$H, $A:$A=$A39, $B:$B<>"""")) ) "),"") | L39: =IF($B39="","", 0.4*$I39 + 0.6*$J39) | M39: =IFERROR(__xludf.DUMMYFUNCTION("IF($B39="""","""", RANK($K39, FILTER($K:$K, $A:$A=$A39, $B:$B<>""""), 0) ) "),"") | N39: =IF($B39="","", IF($L39>=60,"🟢 Strong", IF($L39>=35,"🟡 Watch", "🔴 Action Needed"))) | O39: =IF($B39="","", IF($N39="🟢 Strong","OK", IF($K39<$J39,"Profit issue → pricing/cost/rent", "Traffic issue → location/product mix")))
G40: 0 | H40: =IFERROR( D40 + F40 - G40, 0) -> 0 | I40: =IF(OR($B40="",RIGHT($A40,5)="Total"),"", $C40 / $E40) | J40: =IFERROR(__xludf.DUMMYFUNCTION("IF($B40="""","""", 100 * $E40 / MAX(FILTER($E:$E, $A:$A=$A40, $B:$B<>"""")) ) "),"") | K40: =IFERROR(__xludf.DUMMYFUNCTION("IF($B40="""","""", 100 * $H40 / MAX(FILTER($H:$H, $A:$A=$A40, $B:$B<>"""")) ) "),"") | L40: =IF($B40="","", 0.4*$I40 + 0.6*$J40) | M40: =IFERROR(__xludf.DUMMYFUNCTION("IF($B40="""","""", RANK($K40, FILTER($K:$K, $A:$A=$A40, $B:$B<>""""), 0) ) "),"") | N40: =IF($B40="","", IF($L40>=60,"🟢 Strong", IF($L40>=35,"🟡 Watch", "🔴 Action Needed"))) | O40: =IF($B40="","", IF($N40="🟢 Strong","OK", IF($K40<$J40,"Profit issue → pricing/cost/rent", "Traffic issue → location/product mix")))
G41: 150 | H41: =IFERROR( D41 + F41 - G41, 0) -> 3557 | I41: =IF(OR($B41="",RIGHT($A41,5)="Total"),"", $C41 / $E41) -> 2.5149254 | J41: =IFERROR(__xludf.DUMMYFUNCTION("IF($B41="""","""", 100 * $E41 / MAX(FILTER($E:$E, $A:$A=$A41, $B:$B<>"""")) ) "),32.574585635359114) -> 32.574586 | K41: =IFERROR(__xludf.DUMMYFUNCTION("IF($B41="""","""", 100 * $H41 / MAX(FILTER($H:$H, $A:$A=$A41, $B:$B<>"""")) ) "),65.80505276244322) -> 65.805053 | L41: =IF($B41="","", 0.4*$I41 + 0.6*$J41) -> 20.550722 | M41: =IFERROR(__xludf.DUMMYFUNCTION("IF($B41="""","""", RANK($K41, FILTER($K:$K, $A:$A=$A41, $B:$B<>""""), 0) ) "),6.0) -> 6 | N41: =IF($B41="","", IF($L41>=60,"🟢 Strong", IF($L41>=35,"🟡 Watch", "🔴 Action Needed"))) -> 🔴 Action Needed | O41: =IF($B41="","", IF($N41="🟢 Strong","OK", IF($K41<$J41,"Profit issue → pricing/cost/rent", "Traffic issue → location/product mix"))) -> Traffic issue → location/product mix

Sheet VMS_Sales
A1: Machine code | B1: Machine name | C1: Product Number | D1: product name | E1: Commodity price | F1: Number of transaction | G1: Transaction amount | H1: The refund count | I1: Refund amount | J1: Total Transaction Quantity | K1: Total Transaction Amount | L1: Cost Price | M1: Cost Amount | N1: Profits | O1: MonthKey_Row | P1: MonthKey
A2: 2404120076 | B2: DPMall | D2: Tiger Medium 16 | F2: 19 | G2: 77 | J2: 19 | K2: 77 | L2: 0 | M2: 0 | N2: 77 | O2: 45658 | P2: 45658
A3: 2404120076 | B3: DPMall | D3: Takis | F3: 46 | G3: 820 | J3: 46 | K3: 820 | L3: 0 | M3: 0 | N3: 820 | O3: 45658
A4: 2404120076 | B4: DPMall | D4: Tiger excellence *10 | F4: 88 | G4: 430 | J4: 88 | K4: 430 | L4: 0 | M4: 0 | N4: 430 | O4: 45658
A5: 2404120076 | B5: DPMall | D5: kinza | F5: 29 | G5: 58 | J5: 29 | K5: 58 | L5: 0 | M5: 0 | N5: 58 | O5: 45658
A6: 2404120076 | B6: DPMall | D6: Dark blue energy | F6: 19 | G6: 57 | J6: 19 | K6: 57 | L6: 0 | M6: 0 | N6: 57 | O6: 45658
A7: 2404120076 | B7: DPMall | D7: tiger chips *12 | F7: 152 | G7: 608 | J7: 152 | K7: 608 | L7: 0 | M7: 0 | N7: 608 | O7: 45658
A8: 2404120076 | B8: DPMall | D8: Mr Crunch cheez top | F8: 50 | G8: 200 | J8: 50 | K8: 200 | L8: 0 | M8: 0 | N8: 200 | O8: 45658
A9: 2404120076 | B9: DPMall | D9: popcorn pizza funday | F9: 3 | G9: 15 | J9: 3 | K9: 15 | L9: 0 | M9: 0 | N9: 15 | O9: 45658
A10: 2404120076 | B10: DPMall | D10: ono cake | F10: 88 | G10: 88 | J10: 88 | K10: 88 | L10: 0 | M10: 0 | N10: 88 | O10: 45658
A11: 2404120076 | B11: DPMall | D11: Masa suntop | F11: 320 | G11: 333 | J11: 320 | K11: 333 | L11: 0 | M11: 0 | N11: 333 | O11: 45658
A12: 2404120076 | B12: DPMall | D12: Mr Crunch | F12: 108 | G12: 420 | J12: 108 | K12: 420 | L12: 0 | M12: 0 | N12: 420 | O12: 45658
A13: 2404120076 | B13: DPMall | D13: Roshen Chocolate | F13: 34 | G13: 97 | J13: 34 | K13: 97 | L13: 0 | M13: 0 | N13: 97 | O13: 45658
A14: 2404120076 | B14: DPMall | D14: GoOn Energy chocolate | F14: 1 | G14: 3 | J14: 1 | K14: 3 | L14: 0 | M14: 0 | N14: 3 | O14: 45658
... A38: 2404120076 | B38: DPMall | D38: Tiger Small | F38: 2 | G38: 6 | J38: 2 | K38: 6 | L38: 0 | M38: 0 | N38: 6 | O38: 45658
J39: 0 | K39: 0 | L39: 0 | M39: 0 | N39: 0
A40: 2404120076 | B40: DPMall | D40: Tiger Medium 16 | F40: 31 | G40: 93 | J40: 31 | K40: 93 | L40: 0 | M40: 0 | N40: 93 | O40: 45689 | P40: 45689
A41: 2404120076 | B41: DPMall | D41: Takis | F41: 40 | G41: 768 | J41: 40 | K41: 768 | L41: 0 | M41: 0 | N41: 768 | O41: 45689
A42: 2404120076 | B42: DPMall | D42: Marshmellow sweetBag | F42: 9 | G42: 27 | J42: 9 | K42: 27 | L42: 0 | M42: 0 | N42: 27 | O42: 45689
A43: 2404120076 | B43: DPMall | D43: Tiger excellence *10 | F43: 54 | G43: 268 | J43: 54 | K43: 268 | L43: 0 | M43: 0 | N43: 268 | O43: 45689
A44: 2404120076 | B44: DPMall | D44: vivaldi | F44: 22 | G44: 44 | J44: 22 | K44: 44 | L44: 0 | M44: 0 | N44: 44 | O44: 45689
A45: 2404120076 | B45: DPMall | D45: kinza | F45: 69 | G45: 138 | J45: 69 | K45: 138 | L45: 0 | M45: 0 | N45: 138 | O45: 45689
A46: 2404120076 | B46: DPMall | D46: Tiger excellence super jambo | F46: 10 | G46: 50 | J46: 10 | K46: 50 | L46: 0 | M46: 0 | N46: 50 | O46: 45689
A47: 2404120076 | B47: DPMall | D47: xo energy | F47: 31 | G47: 156 | J47: 31 | K47: 156 | L47: 0 | M47: 0 | N47: 156 | O47: 45689
A48: 2404120076 | B48: DPMall | D48: tiger chips *12 | F48: 174 | G48: 691 | J48: 174 | K48: 691 | L48: 0 | M48: 0 | N48: 691 | O48: 45689
A49: 2404120076 | B49: DPMall | D49: Mr Crunch cheez top | F49: 50 | G49: 200 | J49: 50 | K49: 200 | L49: 0 | M49: 0 | N49: 200 | O49: 45689
A50: 2404120076 | B50: DPMall | D50: popcorn pizza funday | F50: 18 | G50: 84 | J50: 18 | K50: 84 | L50: 0 | M50: 0 | N50: 84 | O50: 45689
A51: 2404120076 | B51: DPMall | D51: ono cake | F51: 61 | G51: 61 | J51: 61 | K51: 61 | L51: 0 | M51: 0 | N51: 61 | O51: 45689
A52: 2404120076 | B52: DPMall | D52: flik flak | F52: 363 | G52: 363 | J52: 363 | K52: 363 | L52: 0 | M52: 0 | N52: 363 | O52: 45689
... A88: 2404120076 | B88: DPMall | D88: Spuds noraml | F88: 8 | G88: 41 | J88: 8 | K88: 41 | L88: 0 | M88: 0 | N88: 41 | O88: 45689
J89: 0 | K89: 0 | L89: 0 | M89: 0 | N89: 0
J90: 0 | K90: 0 | L90: 0 | M90: 0 | N90: 0
J91: 0 | K91: 0 | L91: 0 | M91: 0 | N91: 0
J92: 0 | K92: 0 | L92: 0 | M92: 0 | N92: 0
J93: 0 | K93: 0 | L93: 0 | M93: 0 | N93: 0
A94: 2404120076 | B94: DPMall | D94: Takis | F94: 23 | G94: 428 | J94: 23 | K94: 428 | L94: 0 | M94: 0 | N94: 428 | O94: 45717 | P94: 45717
A95: 2404120076 | B95: DPMall | D95: Tiger excellence *10 | F95: 64 | G95: 320 | J95: 64 | K95: 320 | L95: 0 | M95: 0 | N95: 320 | O95: 45717
A96: 2404120076 | B96: DPMall | D96: kinza | F96: 39 | G96: 78 | J96: 39 | K96: 78 | L96: 0 | M96: 0 | N96: 78 | O96: 45717
A97: 2404120076 | B97: DPMall | D97: xo energy | F97: 30 | G97: 150 | J97: 30 | K97: 150 | L97: 0 | M97: 0 | N97: 150 | O97: 45717
A98: 2404120076 | B98: DPMall | D98: Tiger *12 | F98: 211 | G98: 841 | J98: 211 | K98: 841 | L98: 0 | M98: 0 | N98: 841 | O98: 45717
...

Sheet forcast
A1: Product Name | B1: Last Month | C1: Avg 3M | D1: Forecast | E1: Cost | F1: Forecast Cost | G1: Purchased This Month | H1: Current Stock | I1: Need to Buy | J1: Buy Cost | L1: 46113 | N1: =IFERROR(__xludf.DUMMYFUNCTION("QUERY(A1:J1497,""select * where A is not null and D > 0 order by J desc"",1)"),"Product Name") -> Product Name | O1: =IFERROR(__xludf.DUMMYFUNCTION("""COMPUTED_VALUE"""),"Last Month") -> Last Month | P1: =IFERROR(__xludf.DUMMYFUNCTION("""COMPUTED_VALUE"""),"Avg 3M") -> Avg 3M | Q1: =IFERROR(__xludf.DUMMYFUNCTION("""COMPUTED_VALUE"""),"Forecast") -> Forecast | R1: =IFERROR(__xludf.DUMMYFUNCTION("""COMPUTED_VALUE"""),"Cost") -> Cost | S1: =IFERROR(__xludf.DUMMYFUNCTION("""COMPUTED_VALUE"""),"Forecast Cost") -> Forecast Cost | T1: =IFERROR(__xludf.DUMMYFUNCTION("""COMPUTED_VALUE"""),"Purchased This Month") -> Purchased This Month | U1: =IFERROR(__xludf.DUMMYFUNCTION("""COMPUTED_VALUE"""),"Current Stock") -> Current Stock | V1: =IFERROR(__xludf.DUMMYFUNCTION("""COMPUTED_VALUE"""),"Need to Buy") -> Need to Buy | W1: =IFERROR(__xludf.DUMMYFUNCTION("""COMPUTED_VALUE"""),"Buy Cost") -> Buy Cost
A2: =IFERROR(__xludf.DUMMYFUNCTION("UNIQUE(FILTER( VMS_Sales!D2:D1497, VMS_Sales!D2:D1497<>"""", VMS_Sales!D2:D1497<>""æœ•àë®¾ç½®"", VMS_Sales!O2:O1497>=EDATE($L$1,-2), VMS_Sales!B2:B1497<>""DPMall"" ))"),"Doritos cool ranc") -> Doritos cool ranc | B2: =IF(A2="","",SUMIFS(VMS_Sales!F:F,VMS_Sales!D:D,A2,VMS_Sales!O:O,$L$2)) -> 974 | C2: =IF(A2="","",ROUND(( SUMIFS(VMS_Sales!F:F,VMS_Sales!D:D,A2,VMS_Sales!O:O,$L$1)+ SUMIFS(VMS_Sales!F:F,VMS_Sales!D:D,A2,VMS_Sales!O:O,$L$2)+ SUMIFS(VMS_Sales!F:F,VMS_Sales!D:D,A2,VMS_Sales!O:O,$L$3) )/3,2)) -> 471 | D2: =IF(C2="","",ROUND(C2*1.15,0)) -> 542 | E2: =IFERROR(__xludf.DUMMYFUNCTION("IFERROR(XLOOKUP(A2,FILTER(VMS_Sales!$D:$D,VMS_Sales!$O:$O=$L$2),FILTER(VMS_Sales!$L:$L,VMS_Sales!$O:$O=$L$2),""""),"""")"),2.93) -> 2.93 | F2: =IF(OR(D2="",E2=""),"",ROUND(D2*E2,2)) -> 1588.06 | G2: {=IFERROR( SUMIFS( PurchaseLines_Import!$I:$I, PurchaseLines_Import!$C:$C, TEXT(XLOOKUP(A2,Map!$A:$A,Map!$B:$B,""),"0000"), PurchaseLines_Import!$H:$H, $L$1 ), 0)} -> 750 | H2: {=IFERROR( SUMIFS( Inventory_Import!$D:$D, Inventory_Import!$B:$B, TEXT(XLOOKUP(A2,Map!$A:$A,Map!$B:$B,""),"0000") ), 0)} -> 148 | I2: =IF(A2="","",MAX(D2-H2,0)) -> 394 | J2: =IF(OR(I2="",E2=""),"",ROUND(I2*E2,2)) -> 1154.42 | L2: =EDATE(L1,-1) -> 46082 | N2: =IFERROR(__xludf.DUMMYFUNCTION("""COMPUTED_VALUE"""),"X!R") -> X!R | O2: =IFERROR(__xludf.DUMMYFUNCTION("""COMPUTED_VALUE"""),740.0) -> 740 | P2: =IFERROR(__xludf.DUMMYFUNCTION("""COMPUTED_VALUE"""),383.0) -> 383 | Q2: =IFERROR(__xludf.DUMMYFUNCTION("""COMPUTED_VALUE"""),440.0) -> 440 | R2: =IFERROR(__xludf.DUMMYFUNCTION("""COMPUTED_VALUE"""),4.29) -> 4.29 | S2: =IFERROR(__xludf.DUMMYFUNCTION("""COMPUTED_VALUE"""),1887.6) -> 1887.6 | T2: =IFERROR(__xludf.DUMMYFUNCTION("""COMPUTED_VALUE"""),360.0) -> 360 | U2: =IFERROR(__xludf.DUMMYFUNCTION("""COMPUTED_VALUE"""),59.0) -> 59 | V2: =IFERROR(__xludf.DUMMYFUNCTION("""COMPUTED_VALUE"""),381.0) -> 381 | W2: =IFERROR(__xludf.DUMMYFUNCTION("""COMPUTED_VALUE"""),1634.49) -> 1634.49
A3: =IFERROR(__xludf.DUMMYFUNCTION("""COMPUTED_VALUE"""),"Water") -> Water | B3: =IF(A3="","",SUMIFS(VMS_Sales!F:F,VMS_Sales!D:D,A3,VMS_Sales!O:O,$L$2)) -> 2806 | C3: =IF(A3="","",ROUND(( SUMIFS(VMS_Sales!F:F,VMS_Sales!D:D,A3,VMS_Sales!O:O,$L$1)+ SUMIFS(VMS_Sales!F:F,VMS_Sales!D:D,A3,VMS_Sales!O:O,$L$2)+ SUMIFS(VMS_Sales!F:F,VMS_Sales!D:D,A3,VMS_Sales!O:O,$L$3) )/3,2)) -> 1785.67 | D3: =IF(C3="","",ROUND(C3*1.15,0)) -> 2054 | E3: =IFERROR(__xludf.DUMMYFUNCTION("IFERROR(XLOOKUP(A3,FILTER(VMS_Sales!$D:$D,VMS_Sales!$O:$O=$L$2),FILTER(VMS_Sales!$L:$L,VMS_Sales!$O:$O=$L$2),""""),"""")"),0.28) -> 0.28 | F3: =IF(OR(D3="",E3=""),"",ROUND(D3*E3,2)) -> 575.12 | G3: {=IFERROR( SUMIFS( PurchaseLines_Import!$I:$I, PurchaseLines_Import!$C:$C, TEXT(XLOOKUP(A3,Map!$A:$A,Map!$B:$B,""),"0000"), PurchaseLines_Import!$H:$H, $L$1 ), 0)} -> 2328 | H3: {=IFERROR( SUMIFS( Inventory_Import!$D:$D, Inventory_Import!$B:$B, TEXT(XLOOKUP(A3,Map!$A:$A,Map!$B:$B,""),"0000") ), 0)} -> 84 | I3: =IF(A3="","",MAX(D3-H3,0)) -> 1970 | J3: =IF(OR(I3="",E3=""),"",ROUND(I3*E3,2)) -> 551.6 | L3: =EDATE(L1,-2) -> 46054 | N3: =IFERROR(__xludf.DUMMYFUNCTION("""COMPUTED_VALUE"""),"Doritos cool ranc") -> Doritos cool ranc | O3: =IFERROR(__xludf.DUMMYFUNCTION("""COMPUTED_VALUE"""),974.0) -> 974 | P3: =IFERROR(__xludf.DUMMYFUNCTION("""COMPUTED_VALUE"""),471.0) -> 471 | Q3: =IFERROR(__xludf.DUMMYFUNCTION("""COMPUTED_VALUE"""),542.0) -> 542 | R3: =IFERROR(__xludf.DUMMYFUNCTION("""COMPUTED_VALUE"""),2.93) -> 2.93 | S3: =IFERROR(__xludf.DUMMYFUNCTION("""COMPUTED_VALUE"""),1588.06) -> 1588.06 | T3: =IFERROR(__xludf.DUMMYFUNCTION("""COMPUTED_VALUE"""),750.0) -> 750 | U3: =IFERROR(__xludf.DUMMYFUNCTION("""COMPUTED_VALUE"""),148.0) -> 148 | V3: =IFERROR(__xludf.DUMMYFUNCTION("""COMPUTED_VALUE"""),394.0) -> 394 | W3: =IFERROR(__xludf.DUMMYFUNCTION("""COMPUTED_VALUE"""),1154.42) -> 1154.42
A4: =IFERROR(__xludf.DUMMYFUNCTION("""COMPUTED_VALUE"""),"Maltesers") -> Maltesers | B4: =IF(A4="","",SUMIFS(VMS_Sales!F:F,VMS_Sales!D:D,A4,VMS_Sales!O:O,$L$2)) -> 90 | C4: =IF(A4="","",ROUND(( SUMIFS(VMS_Sales!F:F,VMS_Sales!D:D,A4,VMS_Sales!O:O,$L$1)+ SUMIFS(VMS_Sales!F:F,VMS_Sales!D:D,A4,VMS_Sales!O:O,$L$2)+ SUMIFS(VMS_Sales!F:F,VMS_Sales!D:D,A4,VMS_Sales!O:O,$L$3) )/3,2)) -> 49.67 | D4: =IF(C4="","",ROUND(C4*1.15,0)) -> 57 | E4: =IFERROR(__xludf.DUMMYFUNCTION("IFERROR(XLOOKUP(A4,FILTER(VMS_Sales!$D:$D,VMS_Sales!$O:$O=$L$2),FILTER(VMS_Sales!$L:$L,VMS_Sales!$O:$O=$L$2),""""),"""")"),7.5) -> 7.5 | F4: =IF(OR(D4="",E4=""),"",ROUND(D4*E4,2)) -> 427.5 | G4: {=IFERROR( SUMIFS( PurchaseLines_Import!$I:$I, PurchaseLines_Import!$C:$C, TEXT(XLOOKUP(A4,Map!$A:$A,Map!$B:$B,""),"0000"), PurchaseLines_Import!$H:$H, $L$1 ), 0)} -> 0 | H4: {=IFERROR( SUMIFS( Inventory_Import!$D:$D, Inventory_Import!$B:$B, TEXT(XLOOKUP(A4,Map!$A:$A,Map!$B:$B,""),"0000") ), 0)} -> 0 | I4: =IF(A4="","",MAX(D4-H4,0)) -> 57 | J4: =IF(OR(I4="",E4=""),"",ROUND(I4*E4,2)) -> 427.5 | N4: =IFERROR(__xludf.DUMMYFUNCTION("""COMPUTED_VALUE"""),"MR Crunch") -> MR Crunch | O4: =IFERROR(__xludf.DUMMYFUNCTION("""COMPUTED_VALUE"""),457.0) -> 457 | P4: =IFERROR(__xludf.DUMMYFUNCTION("""COMPUTED_VALUE"""),355.0) -> 355 | Q4: =IFERROR(__xludf.DUMMYFUNCTION("""COMPUTED_VALUE"""),408.0) -> 408 | R4: =IFERROR(__xludf.DUMMYFUNCTION("""COMPUTED_VALUE"""),3.0) -> 3 | S4: =IFERROR(__xludf.DUMMYFUNCTION("""COMPUTED_VALUE"""),1224.0) -> 1224 | T4: =IFERROR(__xludf.DUMMYFUNCTION("""COMPUTED_VALUE"""),450.0) -> 450 | U4: =IFERROR(__xludf.DUMMYFUNCTION("""COMPUTED_VALUE"""),95.0) -> 95 | V4: =IFERROR(__xludf.DUMMYFUNCTION("""COMPUTED_VALUE"""),313.0) -> 313 | W4: =IFERROR(__xludf.DUMMYFUNCTION("""COMPUTED_VALUE"""),939.0) -> 939
A5: =IFERROR(__xludf.DUMMYFUNCTION("""COMPUTED_VALUE"""),"Schweppes") -> Schweppes | B5: =IF(A5="","",SUMIFS(VMS_Sales!F:F,VMS_Sales!D:D,A5,VMS_Sales!O:O,$L$2)) -> 8 | C5: =IF(A5="","",ROUND(( SUMIFS(VMS_Sales!F:F,VMS_Sales!D:D,A5,VMS_Sales!O:O,$L$1)+ SUMIFS(VMS_Sales!F:F,VMS_Sales!D:D,A5,VMS_Sales!O:O,$L$2)+ SUMIFS(VMS_Sales!F:F,VMS_Sales!D:D,A5,VMS_Sales!O:O,$L$3) )/3,2)) -> 7.67 | D5: =IF(C5="","",ROUND(C5*1.15,0)) -> 9 | E5: =IFERROR(__xludf.DUMMYFUNCTION("IFERROR(XLOOKUP(A5,FILTER(VMS_Sales!$D:$D,VMS_Sales!$O:$O=$L$2),FILTER(VMS_Sales!$L:$L,VMS_Sales!$O:$O=$L$2),""""),"""")"),2.0) -> 2 | F5: =IF(OR(D5="",E5=""),"",ROUND(D5*E5,2)) -> 18 | G5: {=IFERROR( SUMIFS( PurchaseLines_Import!$I:$I, PurchaseLines_Import!$C:$C, TEXT(XLOOKUP(A5,Map!$A:$A,Map!$B:$B,""),"0000"), PurchaseLines_Import!$H:$H, $L$1 ), 0)} -> 0 | H5: {=IFERROR( SUMIFS( Inventory_Import!$D:$D, Inventory_Import!$B:$B, TEXT(XLOOKUP(A5,Map!$A:$A,Map!$B:$B,""),"0000") ), 0)} -> 0 | I5: =IF(A5="","",MAX(D5-H5,0)) -> 9 | J5: =IF(OR(I5="",E5=""),"",ROUND(I5*E5,2)) -> 18 | N5: =IFERROR(__xludf.DUMMYFUNCTION("""COMPUTED_VALUE"""),"Pepsi") -> Pepsi | O5: =IFERROR(__xludf.DUMMYFUNCTION("""COMPUTED_VALUE"""),499.0) -> 499 | P5: =IFERROR(__xludf.DUMMYFUNCTION("""COMPUTED_VALUE"""),279.67) -> 279.67 | Q5: =IFERROR(__xludf.DUMMYFUNCTION("""COMPUTED_VALUE"""),322.0) -> 322 | R5: =IFERROR(__xludf.DUMMYFUNCTION("""COMPUTED_VALUE"""),2.25) -> 2.25 | S5: =IFERROR(__xludf.DUMMYFUNCTION("""COMPUTED_VALUE"""),724.5) -> 724.5 | T5: =IFERROR(__xludf.DUMMYFUNCTION("""COMPUTED_VALUE"""),408.0) -> 408 | U5: =IFERROR(__xludf.DUMMYFUNCTION("""COMPUTED_VALUE"""),-5.0) -> -5 | V5: =IFERROR(__xludf.DUMMYFUNCTION("""COMPUTED_VALUE"""),327.0) -> 327 | W5: =IFERROR(__xludf.DUMMYFUNCTION("""COMPUTED_VALUE"""),735.75) -> 735.75
A6: =IFERROR(__xludf.DUMMYFUNCTION("""COMPUTED_VALUE"""),"Xo Energy") -> Xo Energy | B6: =IF(A6="","",SUMIFS(VMS_Sales!F:F,VMS_Sales!D:D,A6,VMS_Sales!O:O,$L$2)) -> 6 | C6: =IF(A6="","",ROUND(( SUMIFS(VMS_Sales!F:F,VMS_Sales!D:D,A6,VMS_Sales!O:O,$L$1)+ SUMIFS(VMS_Sales!F:F,VMS_Sales!D:D,A6,VMS_Sales!O:O,$L$2)+ SUMIFS(VMS_Sales!F:F,VMS_Sales!D:D,A6,VMS_Sales!O:O,$L$3) )/3,2)) -> 16 | D6: =IF(C6="","",ROUND(C6*1.15,0)) -> 18 | E6: =IFERROR(__xludf.DUMMYFUNCTION("IFERROR(XLOOKUP(A6,FILTER(VMS_Sales!$D:$D,VMS_Sales!$O:$O=$L$2),FILTER(VMS_Sales!$L:$L,VMS_Sales!$O:$O=$L$2),""""),"""")"),3.45) -> 3.45 | F6: =IF(OR(D6="",E6=""),"",ROUND(D6*E6,2)) -> 62.1 | G6: {=IFERROR( SUMIFS( PurchaseLines_Import!$I:$I, PurchaseLines_Import!$C:$C, TEXT(XLOOKUP(A6,Map!$A:$A,Map!$B:$B,""),"0000"), PurchaseLines_Import!$H:$H, $L$1 ), 0)} -> 0 | H6: {=IFERROR( SUMIFS( Inventory_Import!$D:$D, Inventory_Import!$B:$B, TEXT(XLOOKUP(A6,Map!$A:$A,Map!$B:$B,""),"0000") ), 0)} -> 0 | I6: =IF(A6="","",MAX(D6-H6,0)) -> 18 | J6: =IF(OR(I6="",E6=""),"",ROUND(I6*E6,2)) -> 62.1 | N6: =IFERROR(__xludf.DUMMYFUNCTION("""COMPUTED_VALUE"""),"Kinder Bueno") -> Kinder Bueno | O6: =IFERROR(__xludf.DUMMYFUNCTION("""COMPUTED_VALUE"""),151.0) -> 151 | P6: =IFERROR(__xludf.DUMMYFUNCTION("""COMPUTED_VALUE"""),90.0) -> 90 | Q6: =IFERROR(__xludf.DUMMYFUNCTION("""COMPUTED_VALUE"""),104.0) -> 104 | R6: =IFERROR(__xludf.DUMMYFUNCTION("""COMPUTED_VALUE"""),7.0) -> 7 | S6: =IFERROR(__xludf.DUMMYFUNCTION("""COMPUTED_VALUE"""),728.0) -> 728 | T6: =IFERROR(__xludf.DUMMYFUNCTION("""COMPUTED_VALUE"""),205.0) -> 205 | U6: =IFERROR(__xludf.DUMMYFUNCTION("""COMPUTED_VALUE"""),7.0) -> 7 | V6: =IFERROR(__xludf.DUMMYFUNCTION("""COMPUTED_VALUE"""),97.0) -> 97 | W6: =IFERROR(__xludf.DUMMYFUNCTION("""COMPUTED_VALUE"""),679.0) -> 679
A7: =IFERROR(__xludf.DUMMYFUNCTION("""COMPUTED_VALUE"""),"X!R") -> X!R | B7: =IF(A7="","",SUMIFS(VMS_Sales!F:F,VMS_Sales!D:D,A7,VMS_Sales!O:O,$L$2)) -> 740 | C7: =IF(A7="","",ROUND(( SUMIFS(VMS_Sales!F:F,VMS_Sales!D:D,A7,VMS_Sales!O:O,$L$1)+ SUMIFS(VMS_Sales!F:F,VMS_Sales!D:D,A7,VMS_Sales!O:O,$L$2)+ SUMIFS(VMS_Sales!F:F,VMS_Sales!D:D,A7,VMS_Sales!O:O,$L$3) )/3,2)) -> 383 | D7: =IF(C7="","",ROUND(C7*1.15,0)) -> 440 | E7: =IFERROR(__xludf.DUMMYFUNCTION("IFERROR(XLOOKUP(A7,FILTER(VMS_Sales!$D:$D,VMS_Sales!$O:$O=$L$2),FILTER(VMS_Sales!$L:$L,VMS_Sales!$O:$O=$L$2),""""),"""")"),4.29) -> 4.29 | F7: =IF(OR(D7="",E7=""),"",ROUND(D7*E7,2)) -> 1887.6 | G7: {=IFERROR( SUMIFS( PurchaseLines_Import!$I:$I, PurchaseLines_Import!$C:$C, TEXT(XLOOKUP(A7,Map!$A:$A,Map!$B:$B,""),"0000"), PurchaseLines_Import!$H:$H, $L$1 ), 0)} -> 360 | H7: {=IFERROR( SUMIFS( Inventory_Import!$D:$D, Inventory_Import!$B:$B, TEXT(XLOOKUP(A7,Map!$A:$A,Map!$B:$B,""),"0000") ), 0)} -> 59 | I7: =IF(A7="","",MAX(D7-H7,0)) -> 381 | J7: =IF(OR(I7="",E7=""),"",ROUND(I7*E7,2)) -> 1634.49 | N7: =IFERROR(__xludf.DUMMYFUNCTION("""COMPUTED_VALUE"""),"Laviva") -> Laviva | O7: =IFERROR(__xludf.DUMMYFUNCTION("""COMPUTED_VALUE"""),373.0) -> 373 | P7: =IFERROR(__xludf.DUMMYFUNCTION("""COMPUTED_VALUE"""),236.0) -> 236 | Q7: =IFERROR(__xludf.DUMMYFUNCTION("""COMPUTED_VALUE"""),271.0) -> 271 | R7: =IFERROR(__xludf.DUMMYFUNCTION("""COMPUTED_VALUE"""),2.25) -> 2.25 | S7: =IFERROR(__xludf.DUMMYFUNCTION("""COMPUTED_VALUE"""),609.75) -> 609.75 | T7: =IFERROR(__xludf.DUMMYFUNCTION("""COMPUTED_VALUE"""),168.0) -> 168 | U7: =IFERROR(__xludf.DUMMYFUNCTION("""COMPUTED_VALUE"""),7.0) -> 7 | V7: =IFERROR(__xludf.DUMMYFUNCTION("""COMPUTED_VALUE"""),264.0) -> 264 | W7: =IFERROR(__xludf.DUMMYFUNCTION("""COMPUTED_VALUE"""),594.0) -> 594
A8: =IFERROR(__xludf.DUMMYFUNCTION("""COMPUTED_VALUE"""),"Kinder Bueno") -> Kinder Bueno | B8: =IF(A8="","",SUMIFS(VMS_Sales!F:F,VMS_Sales!D:D,A8,VMS_Sales!O:O,$L$2)) -> 151 | C8: =IF(A8="","",ROUND(( SUMIFS(VMS_Sales!F:F,VMS_Sales!D:D,A8,VMS_Sales!O:O,$L$1)+ SUMIFS(VMS_Sales!F:F,VMS_Sales!D:D,A8,VMS_Sales!O:O,$L$2)+ SUMIFS(VMS_Sales!F:F,VMS_Sales!D:D,A8,VMS_Sales!O:O,$L$3) )/3,2)) -> 90 | D8: =IF(C8="","",ROUND(C8*1.15,0)) -> 104 | E8: =IFERROR(__xludf.DUMMYFUNCTION("IFERROR(XLOOKUP(A8,FILTER(VMS_Sales!$D:$D,VMS_Sales!$O:$O=$L$2),FILTER(VMS_Sales!$L:$L,VMS_Sales!$O:$O=$L$2),""""),"""")"),7.0) -> 7 | F8: =IF(OR(D8="",E8=""),"",ROUND(D8*E8,2)) -> 728 | G8: {=IFERROR( SUMIFS( PurchaseLines_Import!$I:$I, PurchaseLines_Import!$C:$C, TEXT(XLOOKUP(A8,Map!$A:$A,Map!$B:$B,""),"0000"), PurchaseLines_Import!$H:$H, $L$1 ), 0)} -> 205 | H8: {=IFERROR( SUMIFS( Inventory_Import!$D:$D, Inventory_Import!$B:$B, TEXT(XLOOKUP(A8,Map!$A:$A,Map!$B:$B,""),"0000") ), 0)} -> 7 | I8: =IF(A8="","",MAX(D8-H8,0)) -> 97 | J8: =IF(OR(I8="",E8=""),"",ROUND(I8*E8,2)) -> 679 | N8: =IFERROR(__xludf.DUMMYFUNCTION("""COMPUTED_VALUE"""),"Turbo strips") -> Turbo strips | O8: =IFERROR(__xludf.DUMMYFUNCTION("""COMPUTED_VALUE"""),120.0) -> 120 | P8: =IFERROR(__xludf.DUMMYFUNCTION("""COMPUTED_VALUE"""),121.0) -> 121 | Q8: =IFERROR(__xludf.DUMMYFUNCTION("""COMPUTED_VALUE"""),139.0) -> 139 | R8: =IFERROR(__xludf.DUMMYFUNCTION("""COMPUTED_VALUE"""),4.08) -> 4.08 | S8: =IFERROR(__xludf.DUMMYFUNCTION("""COMPUTED_VALUE"""),567.12) -> 567.12 | T8: =IFERROR(__xludf.DUMMYFUNCTION("""COMPUTED_VALUE"""),138.0) -> 138 | U8: =IFERROR(__xludf.DUMMYFUNCTION("""COMPUTED_VALUE"""),0.0) -> 0 | V8: =IFERROR(__xludf.DUMMYFUNCTION("""COMPUTED_VALUE"""),139.0) -> 139 | W8: =IFERROR(__xludf.DUMMYFUNCTION("""COMPUTED_VALUE"""),567.12) -> 567.12
A9: =IFERROR(__xludf.DUMMYFUNCTION("""COMPUTED_VALUE"""),"mr bite") -> mr bite | B9: =IF(A9="","",SUMIFS(VMS_Sales!F:F,VMS_Sales!D:D,A9,VMS_Sales!O:O,$L$2)) -> 342 | C9: =IF(A9="","",ROUND(( SUMIFS(VMS_Sales!F:F,VMS_Sales!D:D,A9,VMS_Sales!O:O,$L$1)+ SUMIFS(VMS_Sales!F:F,VMS_Sales!D:D,A9,VMS_Sales!O:O,$L$2)+ SUMIFS(VMS_Sales!F:F,VMS_Sales!D:D,A9,VMS_Sales!O:O,$L$3) )/3,2)) -> 188 | D9: =IF(C9="","",ROUND(C9*1.15,0)) -> 216 | E9: =IFERROR(__xludf.DUMMYFUNCTION("IFERROR(XLOOKUP(A9,FILTER(VMS_Sales!$D:$D,VMS_Sales!$O:$O=$L$2),FILTER(VMS_Sales!$L:$L,VMS_Sales!$O:$O=$L$2),""""),"""")"),1.79) -> 1.79 | F9: =IF(OR(D9="",E9=""),"",ROUND(D9*E9,2)) -> 386.64 | G9: {=IFERROR( SUMIFS( PurchaseLines_Import!$I:$I, PurchaseLines_Import!$C:$C, TEXT(XLOOKUP(A9,Map!$A:$A,Map!$B:$B,""),"0000"), PurchaseLines_Import!$H:$H, $L$1 ), 0)} -> 48 | H9: {=IFERROR( SUMIFS( Inventory_Import!$D:$D, Inventory_Import!$B:$B, TEXT(XLOOKUP(A9,Map!$A:$A,Map!$B:$B,""),"0000") ), 0)} -> 6 | I9: =IF(A9="","",MAX(D9-H9,0)) -> 210 | J9: =IF(OR(I9="",E9=""),"",ROUND(I9*E9,2)) -> 375.9 | N9: =IFERROR(__xludf.DUMMYFUNCTION("""COMPUTED_VALUE"""),"Water") -> Water | O9: =IFERROR(__xludf.DUMMYFUNCTION("""COMPUTED_VALUE"""),2806.0) -> 2806 | P9: =IFERROR(__xludf.DUMMYFUNCTION("""COMPUTED_VALUE"""),1785.67) -> 1785.67 | Q9: =IFERROR(__xludf.DUMMYFUNCTION("""COMPUTED_VALUE"""),2054.0) -> 2054 | R9: =IFERROR(__xludf.DUMMYFUNCTION("""COMPUTED_VALUE"""),0.28) -> 0.28 | S9: =IFERROR(__xludf.DUMMYFUNCTION("""COMPUTED_VALUE"""),575.12) -> 575.12 | T9: =IFERROR(__xludf.DUMMYFUNCTION("""COMPUTED_VALUE"""),2328.0) -> 2328 | U9: =IFERROR(__xludf.DUMMYFUNCTION("""COMPUTED_VALUE"""),84.0) -> 84 | V9: =IFERROR(__xludf.DUMMYFUNCTION("""COMPUTED_VALUE"""),1970.0) -> 1970 | W9: =IFERROR(__xludf.DUMMYFUNCTION("""COMPUTED_VALUE"""),551.6) -> 551.6
A10: =IFERROR(__xludf.DUMMYFUNCTION("""COMPUTED_VALUE"""),"Laviva") -> Laviva | B10: =IF(A10="","",SUMIFS(VMS_Sales!F:F,VMS_Sales!D:D,A10,VMS_Sales!O:O,$L$2)) -> 373 | C10: =IF(A10="","",ROUND(( SUMIFS(VMS_Sales!F:F,VMS_Sales!D:D,A10,VMS_Sales!O:O,$L$1)+ SUMIFS(VMS_Sales!F:F,VMS_Sales!D:D,A10,VMS_Sales!O:O,$L$2)+ SUMIFS(VMS_Sales!F:F,VMS_Sales!D:D,A10,VMS_Sales!O:O,$L$3) )/3,2)) -> 236 | D10: =IF(C10="","",ROUND(C10*1.15,0)) -> 271 | E10: =IFERROR(__xludf.DUMMYFUNCTION("IFERROR(XLOOKUP(A10,FILTER(VMS_Sales!$D:$D,VMS_Sales!$O:$O=$L$2),FILTER(VMS_Sales!$L:$L,VMS_Sales!$O:$O=$L$2),""""),"""")"),2.25) -> 2.25 | F10: =IF(OR(D10="",E10=""),"",ROUND(D10*E10,2)) -> 609.75 | G10: {=IFERROR( SUMIFS( PurchaseLines_Import!$I:$I, PurchaseLines_Import!$C:$C, TEXT(XLOOKUP(A10,Map!$A:$A,Map!$B:$B,""),"0000"), PurchaseLines_Import!$H:$H, $L$1 ), 0)} -> 168 | H10: {=IFERROR( SUMIFS( Inventory_Import!$D:$D, Inventory_Import!$B:$B, TEXT(XLOOKUP(A10,Map!$A:$A,Map!$B:$B,""),"0000") ), 0)} -> 7 | I10: =IF(A10="","",MAX(D10-H10,0)) -> 264 | J10: =IF(OR(I10="",E10=""),"",ROUND(I10*E10,2)) -> 594 | N10: =IFERROR(__xludf.DUMMYFUNCTION("""COMPUTED_VALUE"""),"Doritos green hot") -> Doritos green hot | O10: =IFERROR(__xludf.DUMMYFUNCTION("""COMPUTED_VALUE"""),187.0) -> 187 | P10: =IFERROR(__xludf.DUMMYFUNCTION("""COMPUTED_VALUE"""),191.0) -> 191 | Q10: =IFERROR(__xludf.DUMMYFUNCTION("""COMPUTED_VALUE"""),220.0) -> 220 | R10: =IFERROR(__xludf.DUMMYFUNCTION("""COMPUTED_VALUE"""),2.93) -> 2.93 | S10: =IFERROR(__xludf.DUMMYFUNCTION("""COMPUTED_VALUE"""),644.6) -> 644.6 | T10: =IFERROR(__xludf.DUMMYFUNCTION("""COMPUTED_VALUE"""),0.0) -> 0 | U10: =IFERROR(__xludf.DUMMYFUNCTION("""COMPUTED_VALUE"""),73.0) -> 73 | V10: =IFERROR(__xludf.DUMMYFUNCTION("""COMPUTED_VALUE"""),147.0) -> 147 | W10: =IFERROR(__xludf.DUMMYFUNCTION("""COMPUTED_VALUE"""),430.71) -> 430.71
A11: =IFERROR(__xludf.DUMMYFUNCTION("""COMPUTED_VALUE"""),"Freez") -> Freez | B11: =IF(A11="","",SUMIFS(VMS_Sales!F:F,VMS_Sales!D:D,A11,VMS_Sales!O:O,$L$2)) -> 8 | C11: =IF(A11="","",ROUND(( SUMIFS(VMS_Sales!F:F,VMS_Sales!D:D,A11,VMS_Sales!O:O,$L$1)+ SUMIFS(VMS_Sales!F:F,VMS_Sales!D:D,A11,VMS_Sales!O:O,$L$2)+ SUMIFS(VMS_Sales!F:F,VMS_Sales!D:D,A11,VMS_Sales!O:O,$L$3) )/3,2)) -> 4.67 | D11: =IF(C11="","",ROUND(C11*1.15,0)) -> 5 | E11: =IFERROR(__xludf.DUMMYFUNCTION("IFERROR(XLOOKUP(A11,FILTER(VMS_Sales!$D:$D,VMS_Sales!$O:$O=$L$2),FILTER(VMS_Sales!$L:$L,VMS_Sales!$O:$O=$L$2),""""),"""")"),3.41) -> 3.41 | F11: =IF(OR(D11="",E11=""),"",ROUND(D11*E11,2)) -> 17.05 | G11: {=IFERROR( SUMIFS( PurchaseLines_Import!$I:$I, PurchaseLines_Import!$C:$C, TEXT(XLOOKUP(A11,Map!$A:$A,Map!$B:$B,""),"0000"), PurchaseLines_Import!$H:$H, $L$1 ), 0)} -> 0 | H11: {=IFERROR( SUMIFS( Inventory_Import!$D:$D, Inventory_Import!$B:$B, TEXT(XLOOKUP(A11,Map!$A:$A,Map!$B:$B,""),"0000") ), 0)} -> 0 | I11: =IF(A11="","",MAX(D11-H11,0)) -> 5 | J11: =IF(OR(I11="",E11=""),"",ROUND(I11*E11,2)) -> 17.05 | N11: =IFERROR(__xludf.DUMMYFUNCTION("""COMPUTED_VALUE"""),"Maltesers") -> Maltesers | O11: =IFERROR(__xludf.DUMMYFUNCTION("""COMPUTED_VALUE"""),90.0) -> 90 | P11: =IFERROR(__xludf.DUMMYFUNCTION("""COMPUTED_VALUE"""),49.67) -> 49.67 | Q11: =IFERROR(__xludf.DUMMYFUNCTION("""COMPUTED_VALUE"""),57.0) -> 57 | R11: =IFERROR(__xludf.DUMMYFUNCTION("""COMPUTED_VALUE"""),7.5) -> 7.5 | S11: =IFERROR(__xludf.DUMMYFUNCTION("""COMPUTED_VALUE"""),427.5) -> 427.5 | T11: =IFERROR(__xludf.DUMMYFUNCTION("""COMPUTED_VALUE"""),0.0) -> 0 | U11: =IFERROR(__xludf.DUMMYFUNCTION("""COMPUTED_VALUE"""),0.0) -> 0 | V11: =IFERROR(__xludf.DUMMYFUNCTION("""COMPUTED_VALUE"""),57.0) -> 57 | W11: =IFERROR(__xludf.DUMMYFUNCTION("""COMPUTED_VALUE"""),427.5) -> 427.5
